Workbook

Sheet Results
A2: HHCRSP Experiment Results
A5: Instance | B5: Instance Seed | C5: Patients | D5: Caregivers | E5: Services | F5: Dynamic % | G5: Dynamic Requests | H5: Advance Requests | I5: Sync % | J5: Sync Requests | K5: Gurobi ZT | L5: Gurobi Zd | M5: Gurobi Zt2 | N5: Gurobi Zu | O5: Gurobi Uncovered | P5: Gurobi Runtime (s) | Q5: GA Best ZT | R5: GA Best Zd | S5: GA Best Zt3 | T5: GA Best Zu | U5: GA Best Uncovered | V5: GA Best Runtime (s) | W5: GA Gap (%) | X5: GA Mean ZT | Y5: GA SD ZT | Z5: Valid GA Runs | AA5: GA Mean Runtime (s) | AB5: RH ZT | AC5: RH Zd | AD5: RH Zt4 | AE5: RH Zu | AF5: RH Uncovered | AG5: RH Runtime (s) | AH5: Delay Reduction (%) | AI5: GA Coverage (%) | AJ5: RH Coverage (%) | AK5: Coverage Gain (pp) | AL5: GA Objective Check | AM5: Notes
A6: 20-1-1 | B6: 27 | C6: 20 | D6: 4 | E6: 2 | F6: 0.1 | G6: 2 | H6: 18 | I6: 0.1 | J6: 2 | K6: 448.8 | L6: 0 | M6: 448.8 | N6: 0 | O6: 0 | P6: 1 | Q6: =IF(COUNT('GA Runs'!M6:M10)=0,"",MIN('GA Runs'!M6:M10)) -> 448.81 | R6: =IF($Q6="","",INDEX('GA Runs'!E6:E10,MATCH($Q6,'GA Runs'!M6:M10,0))) -> 0 | S6: =IF($Q6="","",INDEX('GA Runs'!F6:F10,MATCH($Q6,'GA Runs'!M6:M10,0))) -> 448.81 | T6: =IF($Q6="","",INDEX('GA Runs'!G6:G10,MATCH($Q6,'GA Runs'!M6:M10,0))) -> 0 | U6: =IF($Q6="","",INDEX('GA Runs'!H6:H10,MATCH($Q6,'GA Runs'!M6:M10,0))) -> 0 | V6: =IF($Q6="","",INDEX('GA Runs'!I6:I10,MATCH($Q6,'GA Runs'!M6:M10,0))) -> 20.5 | W6: =IF(OR($K6="",$Q6="",NOT(ISNUMBER($K6))),"",100*($Q6-$K6)/$K6) -> 0.002228164 | X6: =IF(COUNT('GA Runs'!M6:M10)=0,"",AVERAGE('GA Runs'!M6:M10)) -> 448.81 | Y6: =IF(COUNT('GA Runs'!M6:M10)<2,"",_xlfn.STDEV.S('GA Runs'!M6:M10)) -> 6.3552874e-14 | Z6: =COUNT('GA Runs'!M6:M10) -> 5 | AA6: =IF($Z6=0,"",AVERAGEIF('GA Runs'!M6:M10,">=0",'GA Runs'!I6:I10)) -> 21.786 | AB6: 532.3 | AC6: 95.15 | AD6: 437.14 | AE6: 0 | AF6: 0 | AG6: 2.38 | AH6: =IF(OR($AC6="",$R6="",$AC6=0),"",100*($AC6-$R6)/$AC6) -> 100 | AI6: =IF($U6="","",100*($C6-$U6)/$C6) -> 100 | AJ6: =IF($AF6="","",100*($C6-$AF6)/$C6) -> 100 | AK6: =IF(OR($AI6="",$AJ6=""),"",$AI6-$AJ6) -> 0 | AL6: =IF($Q6="","",IF(ABS($Q6-SUM($R6:$T6))<0.05,"OK","CHECK")) -> OK
A7: 20-1-2 | B7: 27 | C7: 20 | D7: 4 | E7: 2 | F7: 0.25 | G7: 5 | H7: 15 | I7: 0.1 | J7: 2 | K7: 549.8 | L7: 38.2 | M7: 511.6 | N7: 0 | O7: 0 | P7: 2 | Q7: =IF(COUNT('GA Runs'!M11:M15)=0,"",MIN('GA Runs'!M11:M15)) -> 549.85 | R7: =IF($Q7="","",INDEX('GA Runs'!E11:E15,MATCH($Q7,'GA Runs'!M11:M15,0))) -> 38.2 | S7: =IF($Q7="","",INDEX('GA Runs'!F11:F15,MATCH($Q7,'GA Runs'!M11:M15,0))) -> 511.65 | T7: =IF($Q7="","",INDEX('GA Runs'!G11:G15,MATCH($Q7,'GA Runs'!M11:M15,0))) -> 0 | U7: =IF($Q7="","",INDEX('GA Runs'!H11:H15,MATCH($Q7,'GA Runs'!M11:M15,0))) -> 0 | V7: =IF($Q7="","",INDEX('GA Runs'!I11:I15,MATCH($Q7,'GA Runs'!M11:M15,0))) -> 23.24 | W7: =IF(OR($K7="",$Q7="",NOT(ISNUMBER($K7))),"",100*($Q7-$K7)/$K7) -> 0.0090942161 | X7: =IF(COUNT('GA Runs'!M11:M15)=0,"",AVERAGE('GA Runs'!M11:M15)) -> 553.89 | Y7: =IF(COUNT('GA Runs'!M11:M15)<2,"",_xlfn.STDEV.S('GA Runs'!M11:M15)) -> 8.9334316 | Z7: =COUNT('GA Runs'!M11:M15) -> 5 | AA7: =IF($Z7=0,"",AVERAGEIF('GA Runs'!M11:M15,">=0",'GA Runs'!I11:I15)) -> 23.272 | AB7: 843.98 | AC7: 338.13 | AD7: 505.85 | AE7: 0 | AF7: 0 | AG7: 3.26 | AH7: =IF(OR($AC7="",$R7="",$AC7=0),"",100*($AC7-$R7)/$AC7) -> 88.70257 | AI7: =IF($U7="","",100*($C7-$U7)/$C7) -> 100 | AJ7: =IF($AF7="","",100*($C7-$AF7)/$C7) -> 100 | AK7: =IF(OR($AI7="",$AJ7=""),"",$AI7-$AJ7) -> 0 | AL7: =IF($Q7="","",IF(ABS($Q7-SUM($R7:$T7))<0.05,"OK","CHECK")) -> OK
A8: 20-1-3 | B8: 27 | C8: 20 | D8: 4 | E8: 2 | F8: 0.5 | G8: 10 | H8: 10 | I8: 0.1 | J8: 2 | K8: 560.1 | L8: 39.1 | M8: 521 | N8: 0 | O8: 0 | P8: 1 | Q8: =IF(COUNT('GA Runs'!M16:M20)=0,"",MIN('GA Runs'!M16:M20)) -> 584.26 | R8: =IF($Q8="","",INDEX('GA Runs'!E16:E20,MATCH($Q8,'GA Runs'!M16:M20,0))) -> 51.62 | S8: =IF($Q8="","",INDEX('GA Runs'!F16:F20,MATCH($Q8,'GA Runs'!M16:M20,0))) -> 532.64 | T8: =IF($Q8="","",INDEX('GA Runs'!G16:G20,MATCH($Q8,'GA Runs'!M16:M20,0))) -> 0 | U8: =IF($Q8="","",INDEX('GA Runs'!H16:H20,MATCH($Q8,'GA Runs'!M16:M20,0))) -> 0 | V8: =IF($Q8="","",INDEX('GA Runs'!I16:I20,MATCH($Q8,'GA Runs'!M16:M20,0))) -> 22.91 | W8: =IF(OR($K8="",$Q8="",NOT(ISNUMBER($K8))),"",100*($Q8-$K8)/$K8) -> 4.3135154 | X8: =IF(COUNT('GA Runs'!M16:M20)=0,"",AVERAGE('GA Runs'!M16:M20)) -> 601.2 | Y8: =IF(COUNT('GA Runs'!M16:M20)<2,"",_xlfn.STDEV.S('GA Runs'!M16:M20)) -> 21.935732 | Z8: =COUNT('GA Runs'!M16:M20) -> 5 | AA8: =IF($Z8=0,"",AVERAGEIF('GA Runs'!M16:M20,">=0",'GA Runs'!I16:I20)) -> 22.846 | AB8: 5148.47 | AC8: 693.07 | AD8: 455.4 | AE8: 4000 | AF8: 1 | AG8: 1 | AH8: =IF(OR($AC8="",$R8="",$AC8=0),"",100*($AC8-$R8)/$AC8) -> 92.551979 | AI8: =IF($U8="","",100*($C8-$U8)/$C8) -> 100 | AJ8: =IF($AF8="","",100*($C8-$AF8)/$C8) -> 95 | AK8: =IF(OR($AI8="",$AJ8=""),"",$AI8-$AJ8) -> 5 | AL8: =IF($Q8="","",IF(ABS($Q8-SUM($R8:$T8))<0.05,"OK","CHECK")) -> OK
A9: 20-1-4 | B9: 27 | C9: 20 | D9: 4 | E9: 2 | F9: 0.75 | G9: 15 | H9: 5 | I9: 0.1 | J9: 2 | K9: 794.3 | L9: 219.3 | M9: 575 | N9: 0 | O9: 0 | P9: 1 | Q9: =IF(COUNT('GA Runs'!M21:M25)=0,"",MIN('GA Runs'!M21:M25)) -> 794.24 | R9: =IF($Q9="","",INDEX('GA Runs'!E21:E25,MATCH($Q9,'GA Runs'!M21:M25,0))) -> 219.26 | S9: =IF($Q9="","",INDEX('GA Runs'!F21:F25,MATCH($Q9,'GA Runs'!M21:M25,0))) -> 574.97 | T9: =IF($Q9="","",INDEX('GA Runs'!G21:G25,MATCH($Q9,'GA Runs'!M21:M25,0))) -> 0 | U9: =IF($Q9="","",INDEX('GA Runs'!H21:H25,MATCH($Q9,'GA Runs'!M21:M25,0))) -> 0 | V9: =IF($Q9="","",INDEX('GA Runs'!I21:I25,MATCH($Q9,'GA Runs'!M21:M25,0))) -> 14.67 | W9: =IF(OR($K9="",$Q9="",NOT(ISNUMBER($K9))),"",100*($Q9-$K9)/$K9) -> -0.007553821 | X9: =IF(COUNT('GA Runs'!M21:M25)=0,"",AVERAGE('GA Runs'!M21:M25)) -> 799.008 | Y9: =IF(COUNT('GA Runs'!M21:M25)<2,"",_xlfn.STDEV.S('GA Runs'!M21:M25)) -> 8.4921799 | Z9: =COUNT('GA Runs'!M21:M25) -> 5 | AA9: =IF($Z9=0,"",AVERAGEIF('GA Runs'!M21:M25,">=0",'GA Runs'!I21:I25)) -> 14.808 | AB9: 4609.47 | AC9: 1078.39 | AD9: 531.08 | AE9: 3000 | AF9: 1 | AG9: 0.95 | AH9: =IF(OR($AC9="",$R9="",$AC9=0),"",100*($AC9-$R9)/$AC9) -> 79.667838 | AI9: =IF($U9="","",100*($C9-$U9)/$C9) -> 100 | AJ9: =IF($AF9="","",100*($C9-$AF9)/$C9) -> 95 | AK9: =IF(OR($AI9="",$AJ9=""),"",$AI9-$AJ9) -> 5 | AL9: =IF($Q9="","",IF(ABS($Q9-SUM($R9:$T9))<0.05,"OK","CHECK")) -> OK
A10: 20-1-5 | B10: 27 | C10: 20 | D10: 4 | E10: 2 | F10: 0.9 | G10: 18 | H10: 2 | I10: 0.1 | J10: 2 | K10: 946.1 | L10: 397.2 | M10: 548.9 | N10: 0 | O10: 0 | P10: 1 | Q10: =IF(COUNT('GA Runs'!M26:M30)=0,"",MIN('GA Runs'!M26:M30)) -> 946.11 | R10: =IF($Q10="","",INDEX('GA Runs'!E26:E30,MATCH($Q10,'GA Runs'!M26:M30,0))) -> 397.23 | S10: =IF($Q10="","",INDEX('GA Runs'!F26:F30,MATCH($Q10,'GA Runs'!M26:M30,0))) -> 548.88 | T10: =IF($Q10="","",INDEX('GA Runs'!G26:G30,MATCH($Q10,'GA Runs'!M26:M30,0))) -> 0 | U10: =IF($Q10="","",INDEX('GA Runs'!H26:H30,MATCH($Q10,'GA Runs'!M26:M30,0))) -> 0 | V10: =IF($Q10="","",INDEX('GA Runs'!I26:I30,MATCH($Q10,'GA Runs'!M26:M30,0))) -> 15.91 | W10: =IF(OR($K10="",$Q10="",NOT(ISNUMBER($K10))),"",100*($Q10-$K10)/$K10) -> 0.0010569707 | X10: =IF(COUNT('GA Runs'!M26:M30)=0,"",AVERAGE('GA Runs'!M26:M30)) -> 971.182 | Y10: =IF(COUNT('GA Runs'!M26:M30)<2,"",_xlfn.STDEV.S('GA Runs'!M26:M30)) -> 34.33125 | Z10: =COUNT('GA Runs'!M26:M30) -> 5 | AA10: =IF($Z10=0,"",AVERAGEIF('GA Runs'!M26:M30,">=0",'GA Runs'!I26:I30)) -> 15.71 | AB10: 4800.14 | AC10: 1288.16 | AD10: 511.98 | AE10: 3000 | AF10: 1 | AG10: 0.64 | AH10: =IF(OR($AC10="",$R10="",$AC10=0),"",100*($AC10-$R10)/$AC10) -> 69.162992 | AI10: =IF($U10="","",100*($C10-$U10)/$C10) -> 100 | AJ10: =IF($AF10="","",100*($C10-$AF10)/$C10) -> 95 | AK10: =IF(OR($AI10="",$AJ10=""),"",$AI10-$AJ10) -> 5 | AL10: =IF($Q10="","",IF(ABS($Q10-SUM($R10:$T10))<0.05,"OK","CHECK")) -> OK
A11: 20-2-1 | B11: 10 | C11: 20 | D11: 4 | E11: 2 | F11: 0.1 | G11: 2 | H11: 18 | I11: 0.1 | J11: 2 | K11: 480.2 | L11: 2.7 | M11: 477.5 | N11: 0 | O11: 0 | P11: 4 | Q11: =IF(COUNT('GA Runs'!M31:M35)=0,"",MIN('GA Runs'!M31:M35)) -> 480.2 | R11: =IF($Q11="","",INDEX('GA Runs'!E31:E35,MATCH($Q11,'GA Runs'!M31:M35,0))) -> 2.72 | S11: =IF($Q11="","",INDEX('GA Runs'!F31:F35,MATCH($Q11,'GA Runs'!M31:M35,0))) -> 477.48 | T11: =IF($Q11="","",INDEX('GA Runs'!G31:G35,MATCH($Q11,'GA Runs'!M31:M35,0))) -> 0 | U11: =IF($Q11="","",INDEX('GA Runs'!H31:H35,MATCH($Q11,'GA Runs'!M31:M35,0))) -> 0 | V11: =IF($Q11="","",INDEX('GA Runs'!I31:I35,MATCH($Q11,'GA Runs'!M31:M35,0))) -> 22.66 | W11: =IF(OR($K11="",$Q11="",NOT(ISNUMBER($K11))),"",100*($Q11-$K11)/$K11) -> 0 | X11: =IF(COUNT('GA Runs'!M31:M35)=0,"",AVERAGE('GA Runs'!M31:M35)) -> 487.094 | Y11: =IF(COUNT('GA Runs'!M31:M35)<2,"",_xlfn.STDEV.S('GA Runs'!M31:M35)) -> 10.883464 | Z11: =COUNT('GA Runs'!M31:M35) -> 5 | AA11: =IF($Z11=0,"",AVERAGEIF('GA Runs'!M31:M35,">=0",'GA Runs'!I31:I35)) -> 21.386 | AB11: 699.67 | AC11: 189.72 | AD11: 509.95 | AE11: 0 | AF11: 0 | AG11: 6.41 | AH11: =IF(OR($AC11="",$R11="",$AC11=0),"",100*($AC11-$R11)/$AC11) -> 98.566308 | AI11: =IF($U11="","",100*($C11-$U11)/$C11) -> 100 | AJ11: =IF($AF11="","",100*($C11-$AF11)/$C11) -> 100 | AK11: =IF(OR($AI11="",$AJ11=""),"",$AI11-$AJ11) -> 0 | AL11: =IF($Q11="","",IF(ABS($Q11-SUM($R11:$T11))<0.05,"OK","CHECK")) -> OK
A12: 20-2-2 | B12: 10 | C12: 20 | D12: 4 | E12: 2 | F12: 0.25 | G12: 5 | H12: 15 | I12: 0.1 | J12: 2 | K12: 480.2 | L12: 2.7 | M12: 477.5 | N12: 0 | O12: 0 | P12: 2 | Q12: =IF(COUNT('GA Runs'!M36:M40)=0,"",MIN('GA Runs'!M36:M40)) -> 480.2 | R12: =IF($Q12="","",INDEX('GA Runs'!E36:E40,MATCH($Q12,'GA Runs'!M36:M40,0))) -> 2.72 | S12: =IF($Q12="","",INDEX('GA Runs'!F36:F40,MATCH($Q12,'GA Runs'!M36:M40,0))) -> 477.48 | T12: =IF($Q12="","",INDEX('GA Runs'!G36:G40,MATCH($Q12,'GA Runs'!M36:M40,0))) -> 0 | U12: =IF($Q12="","",INDEX('GA Runs'!H36:H40,MATCH($Q12,'GA Runs'!M36:M40,0))) -> 0 | V12: =IF($Q12="","",INDEX('GA Runs'!I36:I40,MATCH($Q12,'GA Runs'!M36:M40,0))) -> 21.29 | W12: =IF(OR($K12="",$Q12="",NOT(ISNUMBER($K12))),"",100*($Q12-$K12)/$K12) -> 0 | X12: =IF(COUNT('GA Runs'!M36:M40)=0,"",AVERAGE('GA Runs'!M36:M40)) -> 490.56 | Y12: =IF(COUNT('GA Runs'!M36:M40)<2,"",_xlfn.STDEV.S('GA Runs'!M36:M40)) -> 16.869412 | Z12: =COUNT('GA Runs'!M36:M40) -> 5 | AA12: =IF($Z12=0,"",AVERAGEIF('GA Runs'!M36:M40,">=0",'GA Runs'!I36:I40)) -> 20.63 | AB12: 1164.68 | AC12: 666.66 | AD12: 498.02 | AE12: 0 | AF12: 0 | AG12: 1.44 | AH12: =IF(OR($AC12="",$R12="",$AC12=0),"",100*($AC12-$R12)/$AC12) -> 99.591996 | AI12: =IF($U12="","",100*($C12-$U12)/$C12) -> 100 | AJ12: =IF($AF12="","",100*($C12-$AF12)/$C12) -> 100 | AK12: =IF(OR($AI12="",$AJ12=""),"",$AI12-$AJ12) -> 0 | AL12: =IF($Q12="","",IF(ABS($Q12-SUM($R12:$T12))<0.05,"OK","CHECK")) -> OK
A13: 20-2-3 | B13: 10 | C13: 20 | D13: 4 | E13: 2 | F13: 0.5 | G13: 10 | H13: 10 | I13: 0.1 | J13: 2 | K13: 561.4 | L13: 79.7 | M13: 481.7 | N13: 0 | O13: 0 | P13: 1 | Q13: =IF(COUNT('GA Runs'!M41:M45)=0,"",MIN('GA Runs'!M41:M45)) -> 561.4 | R13: =IF($Q13="","",INDEX('GA Runs'!E41:E45,MATCH($Q13,'GA Runs'!M41:M45,0))) -> 79.67 | S13: =IF($Q13="","",INDEX('GA Runs'!F41:F45,MATCH($Q13,'GA Runs'!M41:M45,0))) -> 481.73 | T13: =IF($Q13="","",INDEX('GA Runs'!G41:G45,MATCH($Q13,'GA Runs'!M41:M45,0))) -> 0 | U13: =IF($Q13="","",INDEX('GA Runs'!H41:H45,MATCH($Q13,'GA Runs'!M41:M45,0))) -> 0 | V13: =IF($Q13="","",INDEX('GA Runs'!I41:I45,MATCH($Q13,'GA Runs'!M41:M45,0))) -> 23.32 | W13: =IF(OR($K13="",$Q13="",NOT(ISNUMBER($K13))),"",100*($Q13-$K13)/$K13) -> 0 | X13: =IF(COUNT('GA Runs'!M41:M45)=0,"",AVERAGE('GA Runs'!M41:M45)) -> 565.998 | Y13: =IF(COUNT('GA Runs'!M41:M45)<2,"",_xlfn.STDEV.S('GA Runs'!M41:M45)) -> 10.281441 | Z13: =COUNT('GA Runs'!M41:M45) -> 5 | AA13: =IF($Z13=0,"",AVERAGEIF('GA Runs'!M41:M45,">=0",'GA Runs'!I41:I45)) -> 21.274 | AB13: 4261.99 | AC13: 772.21 | AD13: 489.78 | AE13: 3000 | AF13: 1 | AG13: 0.74 | AH13: =IF(OR($AC13="",$R13="",$AC13=0),"",100*($AC13-$R13)/$AC13) -> 89.682858 | AI13: =IF($U13="","",100*($C13-$U13)/$C13) -> 100 | AJ13: =IF($AF13="","",100*($C13-$AF13)/$C13) -> 95 | AK13: =IF(OR($AI13="",$AJ13=""),"",$AI13-$AJ13) -> 5 | AL13: =IF($Q13="","",IF(ABS($Q13-SUM($R13:$T13))<0.05,"OK","CHECK")) -> OK
A14: 20-2-4 | B14: 10 | C14: 20 | D14: 4 | E14: 2 | F14: 0.75 | G14: 15 | H14: 5 | I14: 0.1 | J14: 2 | K14: 792.4 | L14: 271.3 | M14: 521.1 | N14: 0 | O14: 0 | P14: 22 | Q14: =IF(COUNT('GA Runs'!M46:M50)=0,"",MIN('GA Runs'!M46:M50)) -> 794.98 | R14: =IF($Q14="","",INDEX('GA Runs'!E46:E50,MATCH($Q14,'GA Runs'!M46:M50,0))) -> 283.68 | S14: =IF($Q14="","",INDEX('GA Runs'!F46:F50,MATCH($Q14,'GA Runs'!M46:M50,0))) -> 511.3 | T14: =IF($Q14="","",INDEX('GA Runs'!G46:G50,MATCH($Q14,'GA Runs'!M46:M50,0))) -> 0 | U14: =IF($Q14="","",INDEX('GA Runs'!H46:H50,MATCH($Q14,'GA Runs'!M46:M50,0))) -> 0 | V14: =IF($Q14="","",INDEX('GA Runs'!I46:I50,MATCH($Q14,'GA Runs'!M46:M50,0))) -> 15.03 | W14: =IF(OR($K14="",$Q14="",NOT(ISNUMBER($K14))),"",100*($Q14-$K14)/$K14) -> 0.32559313 | X14: =IF(COUNT('GA Runs'!M46:M50)=0,"",AVERAGE('GA Runs'!M46:M50)) -> 801.504 | Y14: =IF(COUNT('GA Runs'!M46:M50)<2,"",_xlfn.STDEV.S('GA Runs'!M46:M50)) -> 8.9333549 | Z14: =COUNT('GA Runs'!M46:M50) -> 5 | AA14: =IF($Z14=0,"",AVERAGEIF('GA Runs'!M46:M50,">=0",'GA Runs'!I46:I50)) -> 14.928 | AB14: 4717.05 | AC14: 1229.45 | AD14: 487.6 | AE14: 3000 | AF14: 1 | AG14: 0.37 | AH14: =IF(OR($AC14="",$R14="",$AC14=0),"",100*($AC14-$R14)/$AC14) -> 76.926268 | AI14: =IF($U14="","",100*($C14-$U14)/$C14) -> 100 | AJ14: =IF($AF14="","",100*($C14-$AF14)/$C14) -> 95 | AK14: =IF(OR($AI14="",$AJ14=""),"",$AI14-$AJ14) -> 5 | AL14: =IF($Q14="","",IF(ABS($Q14-SUM($R14:$T14))<0.05,"OK","CHECK")) -> OK
A15: 20-2-5 | B15: 10 | C15: 20 | D15: 4 | E15: 2 | F15: 0.9 | G15: 18 | H15: 2 | I15: 0.1 | J15: 2 | K15: 850.1 | L15: 337.8 | M15: 512.3 | N15: 0 | O15: 0 | P15: 5 | Q15: =IF(COUNT('GA Runs'!M51:M55)=0,"",MIN('GA Runs'!M51:M55)) -> 850.08 | R15: =IF($Q15="","",INDEX('GA Runs'!E51:E55,MATCH($Q15,'GA Runs'!M51:M55,0))) -> 337.81 | S15: =IF($Q15="","",INDEX('GA Runs'!F51:F55,MATCH($Q15,'GA Runs'!M51:M55,0))) -> 512.27 | T15: =IF($Q15="","",INDEX('GA Runs'!G51:G55,MATCH($Q15,'GA Runs'!M51:M55,0))) -> 0 | U15: =IF($Q15="","",INDEX('GA Runs'!H51:H55,MATCH($Q15,'GA Runs'!M51:M55,0))) -> 0 | V15: =IF($Q15="","",INDEX('GA Runs'!I51:I55,MATCH($Q15,'GA Runs'!M51:M55,0))) -> 15.58 | W15: =IF(OR($K15="",$Q15="",NOT(ISNUMBER($K15))),"",100*($Q15-$K15)/$K15) -> -0.0023526644 | X15: =IF(COUNT('GA Runs'!M51:M55)=0,"",AVERAGE('GA Runs'!M51:M55)) -> 856.24 | Y15: =IF(COUNT('GA Runs'!M51:M55)<2,"",_xlfn.STDEV.S('GA Runs'!M51:M55)) -> 13.774179 | Z15: =COUNT('GA Runs'!M51:M55) -> 5 | AA15: =IF($Z15=0,"",AVERAGEIF('GA Runs'!M51:M55,">=0",'GA Runs'!I51:I55)) -> 15.066 | AB15: 1910.71 | AC15: 1393.09 | AD15: 517.62 | AE15: 0 | AF15: 0 | AG15: 0.36 | AH15: =IF(OR($AC15="",$R15="",$AC15=0),"",100*($AC15-$R15)/$AC15) -> 75.751028 | AI15: =IF($U15="","",100*($C15-$U15)/$C15) -> 100 | AJ15: =IF($AF15="","",100*($C15-$AF15)/$C15) -> 100 | AK15: =IF(OR($AI15="",$AJ15=""),"",$AI15-$AJ15) -> 0 | AL15: =IF($Q15="","",IF(ABS($Q15-SUM($R15:$T15))<0.05,"OK","CHECK")) -> OK
A16: 20-3-1 | B16: 42 | C16: 20 | D16: 4 | E16: 2 | F16: 0.1 | G16: 2 | H16: 18 | I16: 0.1 | J16: 2 | K16: 448.4 | L16: 0 | M16: 448.4 | N16: 0 | O16: 0 | P16: 2 | Q16: =IF(COUNT('GA Runs'!M56:M60)=0,"",MIN('GA Runs'!M56:M60)) -> 448.41 | R16: =IF($Q16="","",INDEX('GA Runs'!E56:E60,MATCH($Q16,'GA Runs'!M56:M60,0))) -> 0 | S16: =IF($Q16="","",INDEX('GA Runs'!F56:F60,MATCH($Q16,'GA Runs'!M56:M60,0))) -> 448.41 | T16: =IF($Q16="","",INDEX('GA Runs'!G56:G60,MATCH($Q16,'GA Runs'!M56:M60,0))) -> 0 | U16: =IF($Q16="","",INDEX('GA Runs'!H56:H60,MATCH($Q16,'GA Runs'!M56:M60,0))) -> 0 | V16: =IF($Q16="","",INDEX('GA Runs'!I56:I60,MATCH($Q16,'GA Runs'!M56:M60,0))) -> 23.49 | W16: =IF(OR($K16="",$Q16="",NOT(ISNUMBER($K16))),"",100*($Q16-$K16)/$K16) -> 0.0022301517 | X16: =IF(COUNT('GA Runs'!M56:M60)=0,"",AVERAGE('GA Runs'!M56:M60)) -> 454.208 | Y16: =IF(COUNT('GA Runs'!M56:M60)<2,"",_xlfn.STDEV.S('GA Runs'!M56:M60)) -> 6.5971714 | Z16: =COUNT('GA Runs'!M56:M60) -> 5 | AA16: =IF($Z16=0,"",AVERAGEIF('GA Runs'!M56:M60,">=0",'GA Runs'!I56:I60)) -> 21.784 | AB16: 704 | AC16: 270.67 | AD16: 433.33 | AE16: 0 | AF16: 0 | AG16: 1.54 | AH16: =IF(OR($AC16="",$R16="",$AC16=0),"",100*($AC16-$R16)/$AC16) -> 100 | AI16: =IF($U16="","",100*($C16-$U16)/$C16) -> 100 | AJ16: =IF($AF16="","",100*($C16-$AF16)/$C16) -> 100 | AK16: =IF(OR($AI16="",$AJ16=""),"",$AI16-$AJ16) -> 0 | AL16: =IF($Q16="","",IF(ABS($Q16-SUM($R16:$T16))<0.05,"OK","CHECK")) -> OK
A17: 20-3-2 | B17: 42 | C17: 20 | D17: 4 | E17: 2 | F17: 0.25 | G17: 5 | H17: 15 | I17: 0.1 | J17: 2 | K17: 462.8 | L17: 11.4 | M17: 451.4 | N17: 0 | O17: 0 | P17: 1 | Q17: =IF(COUNT('GA Runs'!M61:M65)=0,"",MIN('GA Runs'!M61:M65)) -> 475.18 | R17: =IF($Q17="","",INDEX('GA Runs'!E61:E65,MATCH($Q17,'GA Runs'!M61:M65,0))) -> 18.5 | S17: =IF($Q17="","",INDEX('GA Runs'!F61:F65,MATCH($Q17,'GA Runs'!M61:M65,0))) -> 456.68 | T17: =IF($Q17="","",INDEX('GA Runs'!G61:G65,MATCH($Q17,'GA Runs'!M61:M65,0))) -> 0 | U17: =IF($Q17="","",INDEX('GA Runs'!H61:H65,MATCH($Q17,'GA Runs'!M61:M65,0))) -> 0 | V17: =IF($Q17="","",INDEX('GA Runs'!I61:I65,MATCH($Q17,'GA Runs'!M61:M65,0))) -> 19.48 | W17: =IF(OR($K17="",$Q17="",NOT(ISNUMBER($K17))),"",100*($Q17-$K17)/$K17) -> 2.6750216 | X17: =IF(COUNT('GA Runs'!M61:M65)=0,"",AVERAGE('GA Runs'!M61:M65)) -> 488.964 | Y17: =IF(COUNT('GA Runs'!M61:M65)<2,"",_xlfn.STDEV.S('GA Runs'!M61:M65)) -> 12.104994 | Z17: =COUNT('GA Runs'!M61:M65) -> 5 | AA17: =IF($Z17=0,"",AVERAGEIF('GA Runs'!M61:M65,">=0",'GA Runs'!I61:I65)) -> 19.458 | AB17: 1132.37 | AC17: 640.78 | AD17: 491.59 | AE17: 0 | AF17: 0 | AG17: 1.85 | AH17: =IF(OR($AC17="",$R17="",$AC17=0),"",100*($AC17-$R17)/$AC17) -> 97.112894 | AI17: =IF($U17="","",100*($C17-$U17)/$C17) -> 100 | AJ17: =IF($AF17="","",100*($C17-$AF17)/$C17) -> 100 | AK17: =IF(OR($AI17="",$AJ17=""),"",$AI17-$AJ17) -> 0 | AL17: =IF($Q17="","",IF(ABS($Q17-SUM($R17:$T17))<0.05,"OK","CHECK")) -> OK
A18: 20-3-3 | B18: 42 | C18: 20 | D18: 4 | E18: 2 | F18: 0.5 | G18: 10 | H18: 10 | I18: 0.1 | J18: 2 | K18: 576.3 | L18: 121.2 | M18: 455.1 | N18: 0 | O18: 0 | P18: 3 | Q18: =IF(COUNT('GA Runs'!M66:M70)=0,"",MIN('GA Runs'!M66:M70)) -> 576.31 | R18: =IF($Q18="","",INDEX('GA Runs'!E66:E70,MATCH($Q18,'GA Runs'!M66:M70,0))) -> 121.19 | S18: =IF($Q18="","",INDEX('GA Runs'!F66:F70,MATCH($Q18,'GA Runs'!M66:M70,0))) -> 455.12 | T18: =IF($Q18="","",INDEX('GA Runs'!G66:G70,MATCH($Q18,'GA Runs'!M66:M70,0))) -> 0 | U18: =IF($Q18="","",INDEX('GA Runs'!H66:H70,MATCH($Q18,'GA Runs'!M66:M70,0))) -> 0 | V18: =IF($Q18="","",INDEX('GA Runs'!I66:I70,MATCH($Q18,'GA Runs'!M66:M70,0))) -> 19.2 | W18: =IF(OR($K18="",$Q18="",NOT(ISNUMBER($K18))),"",100*($Q18-$K18)/$K18) -> 0.0017352074 | X18: =IF(COUNT('GA Runs'!M66:M70)=0,"",AVERAGE('GA Runs'!M66:M70)) -> 702.518 | Y18: =IF(COUNT('GA Runs'!M66:M70)<2,"",_xlfn.STDEV.S('GA Runs'!M66:M70)) -> 71.273816 | Z18: =COUNT('GA Runs'!M66:M70) -> 5 | AA18: =IF($Z18=0,"",AVERAGEIF('GA Runs'!M66:M70,">=0",'GA Runs'!I66:I70)) -> 18.834 | AB18: 4121.43 | AC18: 656.95 | AD18: 464.47 | AE18: 3000 | AF18: 1 | AG18: 0.8 | AH18: =IF(OR($AC18="",$R18="",$AC18=0),"",100*($AC18-$R18)/$AC18) -> 81.55263 | AI18: =IF($U18="","",100*($C18-$U18)/$C18) -> 100 | AJ18: =IF($AF18="","",100*($C18-$AF18)/$C18) -> 95 | AK18: =IF(OR($AI18="",$AJ18=""),"",$AI18-$AJ18) -> 5 | AL18: =IF($Q18="","",IF(ABS($Q18-SUM($R18:$T18))<0.05,"OK","CHECK")) -> OK
A19: 20-3-4 | B19: 42 | C19: 20 | D19: 4 | E19: 2 | F19: 0.75 | G19: 15 | H19: 5 | I19: 0.1 | J19: 2 | K19: 803.8 | L19: 336.1 | M19: 467.7 | N19: 0 | O19: 0 | P19: 4 | Q19: =IF(COUNT('GA Runs'!M71:M75)=0,"",MIN('GA Runs'!M71:M75)) -> 805.65 | R19: =IF($Q19="","",INDEX('GA Runs'!E71:E75,MATCH($Q19,'GA Runs'!M71:M75,0))) -> 337.92 | S19: =IF($Q19="","",INDEX('GA Runs'!F71:F75,MATCH($Q19,'GA Runs'!M71:M75,0))) -> 467.73 | T19: =IF($Q19="","",INDEX('GA Runs'!G71:G75,MATCH($Q19,'GA Runs'!M71:M75,0))) -> 0 | U19: =IF($Q19="","",INDEX('GA Runs'!H71:H75,MATCH($Q19,'GA Runs'!M71:M75,0))) -> 0 | V19: =IF($Q19="","",INDEX('GA Runs'!I71:I75,MATCH($Q19,'GA Runs'!M71:M75,0))) -> 15.62 | W19: =IF(OR($K19="",$Q19="",NOT(ISNUMBER($K19))),"",100*($Q19-$K19)/$K19) -> 0.23015676 | X19: =IF(COUNT('GA Runs'!M71:M75)=0,"",AVERAGE('GA Runs'!M71:M75)) -> 855.034 | Y19: =IF(COUNT('GA Runs'!M71:M75)<2,"",_xlfn.STDEV.S('GA Runs'!M71:M75)) -> 48.348324 | Z19: =COUNT('GA Runs'!M71:M75) -> 5 | AA19: =IF($Z19=0,"",AVERAGEIF('GA Runs'!M71:M75,">=0",'GA Runs'!I71:I75)) -> 15.404 | AB19: 7487.96 | AC19: 1064.14 | AD19: 423.82 | AE19: 6000 | AF19: 2 | AG19: 0.64 | AH19: =IF(OR($AC19="",$R19="",$AC19=0),"",100*($AC19-$R19)/$AC19) -> 68.24478 | AI19: =IF($U19="","",100*($C19-$U19)/$C19) -> 100 | AJ19: =IF($AF19="","",100*($C19-$AF19)/$C19) -> 90 | AK19: =IF(OR($AI19="",$AJ19=""),"",$AI19-$AJ19) -> 10 | AL19: =IF($Q19="","",IF(ABS($Q19-SUM($R19:$T19))<0.05,"OK","CHECK")) -> OK
A20: 20-3-5 | B20: 42 | C20: 20 | D20: 4 | E20: 2 | F20: 0.9 | G20: 18 | H20: 2 | I20: 0.1 | J20: 2 | K20: 976.2 | L20: 429.9 | M20: 546.3 | N20: 0 | O20: 0 | P20: 14 | Q20: =IF(COUNT('GA Runs'!M76:M80)=0,"",MIN('GA Runs'!M76:M80)) -> 976.12 | R20: =IF($Q20="","",INDEX('GA Runs'!E76:E80,MATCH($Q20,'GA Runs'!M76:M80,0))) -> 429.86 | S20: =IF($Q20="","",INDEX('GA Runs'!F76:F80,MATCH($Q20,'GA Runs'!M76:M80,0))) -> 546.26 | T20: =IF($Q20="","",INDEX('GA Runs'!G76:G80,MATCH($Q20,'GA Runs'!M76:M80,0))) -> 0 | U20: =IF($Q20="","",INDEX('GA Runs'!H76:H80,MATCH($Q20,'GA Runs'!M76:M80,0))) -> 0 | V20: =IF($Q20="","",INDEX('GA Runs'!I76:I80,MATCH($Q20,'GA Runs'!M76:M80,0))) -> 15.14 | W20: =IF(OR($K20="",$Q20="",NOT(ISNUMBER($K20))),"",100*($Q20-$K20)/$K20) -> -0.008195042 | X20: =IF(COUNT('GA Runs'!M76:M80)=0,"",AVERAGE('GA Runs'!M76:M80)) -> 985.954 | Y20: =IF(COUNT('GA Runs'!M76:M80)<2,"",_xlfn.STDEV.S('GA Runs'!M76:M80)) -> 11.590586 | Z20: =COUNT('GA Runs'!M76:M80) -> 5 | AA20: =IF($Z20=0,"",AVERAGEIF('GA Runs'!M76:M80,">=0",'GA Runs'!I76:I80)) -> 15.028 | AB20: 5689.48 | AC20: 1283.47 | AD20: 406.01 | AE20: 4000 | AF20: 1 | AG20: 0.6 | AH20: =IF(OR($AC20="",$R20="",$AC20=0),"",100*($AC20-$R20)/$AC20) -> 66.507982 | AI20: =IF($U20="","",100*($C20-$U20)/$C20) -> 100 | AJ20: =IF($AF20="","",100*($C20-$AF20)/$C20) -> 95 | AK20: =IF(OR($AI20="",$AJ20=""),"",$AI20-$AJ20) -> 5 | AL20: =IF($Q20="","",IF(ABS($Q20-SUM($R20:$T20))<0.05,"OK","CHECK")) -> OK
A21: 20-4-1 | B21: 64 | C21: 20 | D21: 4 | E21: 2 | F21: 0.1 | G21: 2 | H21: 18 | I21: 0.1 | J21: 2 | K21: 524.2 | L21: 43.4 | M21: 480.8 | N21: 0 | O21: 0 | P21: 1 | Q21: =IF(COUNT('GA Runs'!M81:M85)=0,"",MIN('GA Runs'!M81:M85)) -> 525.31 | R21: =IF($Q21="","",INDEX('GA Runs'!E81:E85,MATCH($Q21,'GA Runs'!M81:M85,0))) -> 43.4 | S21: =IF($Q21="","",INDEX('GA Runs'!F81:F85,MATCH($Q21,'GA Runs'!M81:M85,0))) -> 481.91 | T21: =IF($Q21="","",INDEX('GA Runs'!G81:G85,MATCH($Q21,'GA Runs'!M81:M85,0))) -> 0 | U21: =IF($Q21="","",INDEX('GA Runs'!H81:H85,MATCH($Q21,'GA Runs'!M81:M85,0))) -> 0 | V21: =IF($Q21="","",INDEX('GA Runs'!I81:I85,MATCH($Q21,'GA Runs'!M81:M85,0))) -> 22.3 | W21: =IF(OR($K21="",$Q21="",NOT(ISNUMBER($K21))),"",100*($Q21-$K21)/$K21) -> 0.21175124 | X21: =IF(COUNT('GA Runs'!M81:M85)=0,"",AVERAGE('GA Runs'!M81:M85)) -> 528.404 | Y21: =IF(COUNT('GA Runs'!M81:M85)<2,"",_xlfn.STDEV.S('GA Runs'!M81:M85)) -> 4.2534903 | Z21: =COUNT('GA Runs'!M81:M85) -> 5 | AA21: =IF($Z21=0,"",AVERAGEIF('GA Runs'!M81:M85,">=0",'GA Runs'!I81:I85)) -> 21.224 | AB21: 646.31 | AC21: 163.54 | AD21: 482.77 | AE21: 0 | AF21: 0 | AG21: 1.8 | AH21: =IF(OR($AC21="",$R21="",$AC21=0),"",100*($AC21-$R21)/$AC21) -> 73.46215 | AI21: =IF($U21="","",100*($C21-$U21)/$C21) -> 100 | AJ21: =IF($AF21="","",100*($C21-$AF21)/$C21) -> 100 | AK21: =IF(OR($AI21="",$AJ21=""),"",$AI21-$AJ21) -> 0 | AL21: =IF($Q21="","",IF(ABS($Q21-SUM($R21:$T21))<0.05,"OK","CHECK")) -> OK
A22: 20-4-2 | B22: 64 | C22: 20 | D22: 4 | E22: 2 | F22: 0.25 | G22: 5 | H22: 15 | I22: 0.1 | J22: 2 | K22: 539.4 | L22: 43.4 | M22: 496 | N22: 0 | O22: 0 | P22: 1 | Q22: =IF(COUNT('GA Runs'!M86:M90)=0,"",MIN('GA Runs'!M86:M90)) -> 539.41 | R22: =IF($Q22="","",INDEX('GA Runs'!E86:E90,MATCH($Q22,'GA Runs'!M86:M90,0))) -> 43.4 | S22: =IF($Q22="","",INDEX('GA Runs'!F86:F90,MATCH($Q22,'GA Runs'!M86:M90,0))) -> 496.01 | T22: =IF($Q22="","",INDEX('GA Runs'!G86:G90,MATCH($Q22,'GA Runs'!M86:M90,0))) -> 0 | U22: =IF($Q22="","",INDEX('GA Runs'!H86:H90,MATCH($Q22,'GA Runs'!M86:M90,0))) -> 0 | V22: =IF($Q22="","",INDEX('GA Runs'!I86:I90,MATCH($Q22,'GA Runs'!M86:M90,0))) -> 21.88 | W22: =IF(OR($K22="",$Q22="",NOT(ISNUMBER($K22))),"",100*($Q22-$K22)/$K22) -> 0.0018539118 | X22: =IF(COUNT('GA Runs'!M86:M90)=0,"",AVERAGE('GA Runs'!M86:M90)) -> 544.34 | Y22: =IF(COUNT('GA Runs'!M86:M90)<2,"",_xlfn.STDEV.S('GA Runs'!M86:M90)) -> 8.3024274 | Z22: =COUNT('GA Runs'!M86:M90) -> 5 | AA22: =IF($Z22=0,"",AVERAGEIF('GA Runs'!M86:M90,">=0",'GA Runs'!I86:I90)) -> 21.276 | AB22: 929.76 | AC22: 426.3 | AD22: 503.46 | AE22: 0 | AF22: 0 | AG22: 1.56 | AH22: =IF(OR($AC22="",$R22="",$AC22=0),"",100*($AC22-$R22)/$AC22) -> 89.819376 | AI22: =IF($U22="","",100*($C22-$U22)/$C22) -> 100 | AJ22: =IF($AF22="","",100*($C22-$AF22)/$C22) -> 100 | AK22: =IF(OR($AI22="",$AJ22=""),"",$AI22-$AJ22) -> 0 | AL22: =IF($Q22="","",IF(ABS($Q22-SUM($R22:$T22))<0.05,"OK","CHECK")) -> OK
A23: 20-4-3 | B23: 64 | C23: 20 | D23: 4 | E23: 2 | F23: 0.5 | G23: 10 | H23: 10 | I23: 0.1 | J23: 2 | K23: 693.7 | L23: 194.2 | M23: 499.5 | N23: 0 | O23: 0 | P23: 1 | Q23: =IF(COUNT('GA Runs'!M91:M95)=0,"",MIN('GA Runs'!M91:M95)) -> 693.73 | R23: =IF($Q23="","",INDEX('GA Runs'!E91:E95,MATCH($Q23,'GA Runs'!M91:M95,0))) -> 194.24 | S23: =IF($Q23="","",INDEX('GA Runs'!F91:F95,MATCH($Q23,'GA Runs'!M91:M95,0))) -> 499.49 | T23: =IF($Q23="","",INDEX('GA Runs'!G91:G95,MATCH($Q23,'GA Runs'!M91:M95,0))) -> 0 | U23: =IF($Q23="","",INDEX('GA Runs'!H91:H95,MATCH($Q23,'GA Runs'!M91:M95,0))) -> 0 | V23: =IF($Q23="","",INDEX('GA Runs'!I91:I95,MATCH($Q23,'GA Runs'!M91:M95,0))) -> 13.85 | W23: =IF(OR($K23="",$Q23="",NOT(ISNUMBER($K23))),"",100*($Q23-$K23)/$K23) -> 0.004324636 | X23: =IF(COUNT('GA Runs'!M91:M95)=0,"",AVERAGE('GA Runs'!M91:M95)) -> 700.69 | Y23: =IF(COUNT('GA Runs'!M91:M95)<2,"",_xlfn.STDEV.S('GA Runs'!M91:M95)) -> 8.180599 | Z23: =COUNT('GA Runs'!M91:M95) -> 5 | AA23: =IF($Z23=0,"",AVERAGEIF('GA Runs'!M91:M95,">=0",'GA Runs'!I91:I95)) -> 15.052 | AB23: 1189.66 | AC23: 682.94 | AD23: 506.72 | AE23: 0 | AF23: 0 | AG23: 1.03 | AH23: =IF(OR($AC23="",$R23="",$AC23=0),"",100*($AC23-$R23)/$AC23) -> 71.558263 | AI23: =IF($U23="","",100*($C23-$U23)/$C23) -> 100 | AJ23: =IF($AF23="","",100*($C23-$AF23)/$C23) -> 100 | AK23: =IF(OR($AI23="",$AJ23=""),"",$AI23-$AJ23) -> 0 | AL23: =IF($Q23="","",IF(ABS($Q23-SUM($R23:$T23))<0.05,"OK","CHECK")) -> OK
A24: 20-4-4 | B24: 64 | C24: 20 | D24: 4 | E24: 2 | F24: 0.75 | G24: 15 | H24: 5 | I24: 0.1 | J24: 2 | K24: 1068.8 | L24: 493.9 | M24: 574.9 | N24: 0 | O24: 0 | P24: 11 | Q24: =IF(COUNT('GA Runs'!M96:M100)=0,"",MIN('GA Runs'!M96:M100)) -> 1068.82 | R24: =IF($Q24="","",INDEX('GA Runs'!E96:E100,MATCH($Q24,'GA Runs'!M96:M100,0))) -> 493.92 | S24: =IF($Q24="","",INDEX('GA Runs'!F96:F100,MATCH($Q24,'GA Runs'!M96:M100,0))) -> 574.9 | T24: =IF($Q24="","",INDEX('GA Runs'!G96:G100,MATCH($Q24,'GA Runs'!M96:M100,0))) -> 0 | U24: =IF($Q24="","",INDEX('GA Runs'!H96:H100,MATCH($Q24,'GA Runs'!M96:M100,0))) -> 0 | V24: =IF($Q24="","",INDEX('GA Runs'!I96:I100,MATCH($Q24,'GA Runs'!M96:M100,0))) -> 16.21 | W24: =IF(OR($K24="",$Q24="",NOT(ISNUMBER($K24))),"",100*($Q24-$K24)/$K24) -> 0.0018712575 | X24: =IF(COUNT('GA Runs'!M96:M100)=0,"",AVERAGE('GA Runs'!M96:M100)) -> 1115.544 | Y24: =IF(COUNT('GA Runs'!M96:M100)<2,"",_xlfn.STDEV.S('GA Runs'!M96:M100)) -> 43.360482 | Z24: =COUNT('GA Runs'!M96:M100) -> 5 | AA24: =IF($Z24=0,"",AVERAGEIF('GA Runs'!M96:M100,">=0",'GA Runs'!I96:I100)) -> 15.774 | AB24: 1957.42 | AC24: 1390.85 | AD24: 566.57 | AE24: 0 | AF24: 0 | AG24: 0.35 | AH24: =IF(OR($AC24="",$R24="",$AC24=0),"",100*($AC24-$R24)/$AC24) -> 64.487903 | AI24: =IF($U24="","",100*($C24-$U24)/$C24) -> 100 | AJ24: =IF($AF24="","",100*($C24-$AF24)/$C24) -> 100 | AK24: =IF(OR($AI24="",$AJ24=""),"",$AI24-$AJ24) -> 0 | AL24: =IF($Q24="","",IF(ABS($Q24-SUM($R24:$T24))<0.05,"OK","CHECK")) -> OK
A25: 20-4-5 | B25: 64 | C25: 20 | D25: 4 | E25: 2 | F25: 0.9 | G25: 18 | H25: 2 | I25: 0.1 | J25: 2 | K25: 1142.7 | L25: 600.6 | M25: 542.1 | N25: 0 | O25: 0 | P25: 10 | Q25: =IF(COUNT('GA Runs'!M101:M105)=0,"",MIN('GA Runs'!M101:M105)) -> 1142.7 | R25: =IF($Q25="","",INDEX('GA Runs'!E101:E105,MATCH($Q25,'GA Runs'!M101:M105,0))) -> 600.57 | S25: =IF($Q25="","",INDEX('GA Runs'!F101:F105,MATCH($Q25,'GA Runs'!M101:M105,0))) -> 542.14 | T25: =IF($Q25="","",INDEX('GA Runs'!G101:G105,MATCH($Q25,'GA Runs'!M101:M105,0))) -> 0 | U25: =IF($Q25="","",INDEX('GA Runs'!H101:H105,MATCH($Q25,'GA Runs'!M101:M105,0))) -> 0 | V25: =IF($Q25="","",INDEX('GA Runs'!I101:I105,MATCH($Q25,'GA Runs'!M101:M105,0))) -> 14.9 | W25: =IF(OR($K25="",$Q25="",NOT(ISNUMBER($K25))),"",100*($Q25-$K25)/$K25) -> 0 | X25: =IF(COUNT('GA Runs'!M101:M105)=0,"",AVERAGE('GA Runs'!M101:M105)) -> 1183.904 | Y25: =IF(COUNT('GA Runs'!M101:M105)<2,"",_xlfn.STDEV.S('GA Runs'!M101:M105)) -> 76.038162 | Z25: =COUNT('GA Runs'!M101:M105) -> 5 | AA25: =IF($Z25=0,"",AVERAGEIF('GA Runs'!M101:M105,">=0",'GA Runs'!I101:I105)) -> 15.244 | AB25: 5159.95 | AC25: 1641.77 | AD25: 518.17 | AE25: 3000 | AF25: 1 | AG25: 0.42 | AH25: =IF(OR($AC25="",$R25="",$AC25=0),"",100*($AC25-$R25)/$AC25) -> 63.419358 | AI25: =IF($U25="","",100*($C25-$U25)/$C25) -> 100 | AJ25: =IF($AF25="","",100*($C25-$AF25)/$C25) -> 95 | AK25: =IF(OR($AI25="",$AJ25=""),"",$AI25-$AJ25) -> 5 | AL25: =IF($Q25="","",IF(ABS($Q25-SUM($R25:$T25))<0.05,"OK","CHECK")) -> OK
A26: 20-5-1 | B26: 73 | C26: 20 | D26: 4 | E26: 2 | F26: 0.1 | G26: 2 | H26: 18 | I26: 0.1 | J26: 2 | K26: 481.2 | L26: 23.5 | M26: 457.7 | N26: 0 | O26: 0 | P26: 1 | Q26: =IF(COUNT('GA Runs'!M106:M110)=0,"",MIN('GA Runs'!M106:M110)) -> 484.04 | R26: =IF($Q26="","",INDEX('GA Runs'!E106:E110,MATCH($Q26,'GA Runs'!M106:M110,0))) -> 23.53 | S26: =IF($Q26="","",INDEX('GA Runs'!F106:F110,MATCH($Q26,'GA Runs'!M106:M110,0))) -> 460.52 | T26: =IF($Q26="","",INDEX('GA Runs'!G106:G110,MATCH($Q26,'GA Runs'!M106:M110,0))) -> 0 | U26: =IF($Q26="","",INDEX('GA Runs'!H106:H110,MATCH($Q26,'GA Runs'!M106:M110,0))) -> 0 | V26: =IF($Q26="","",INDEX('GA Runs'!I106:I110,MATCH($Q26,'GA Runs'!M106:M110,0))) -> 19.87 | W26: =IF(OR($K26="",$Q26="",NOT(ISNUMBER($K26))),"",100*($Q26-$K26)/$K26) -> 0.59019119 | X26: =IF(COUNT('GA Runs'!M106:M110)=0,"",AVERAGE('GA Runs'!M106:M110)) -> 499.354 | Y26: =IF(COUNT('GA Runs'!M106:M110)<2,"",_xlfn.STDEV.S('GA Runs'!M106:M110)) -> 9.662271 | Z26: =COUNT('GA Runs'!M106:M110) -> 5 | AA26: =IF($Z26=0,"",AVERAGEIF('GA Runs'!M106:M110,">=0",'GA Runs'!I106:I110)) -> 21.478 | AB26: 589.18 | AC26: 143.54 | AD26: 445.64 | AE26: 0 | AF26: 0 | AG26: 1.03 | AH26: =IF(OR($AC26="",$R26="",$AC26=0),"",100*($AC26-$R26)/$AC26) -> 83.607357 | AI26: =IF($U26="","",100*($C26-$U26)/$C26) -> 100 | AJ26: =IF($AF26="","",100*($C26-$AF26)/$C26) -> 100 | AK26: =IF(OR($AI26="",$AJ26=""),"",$AI26-$AJ26) -> 0 | AL26: =IF($Q26="","",IF(ABS($Q26-SUM($R26:$T26))<0.05,"OK","CHECK")) -> OK
A27: 20-5-2 | B27: 73 | C27: 20 | D27: 4 | E27: 2 | F27: 0.25 | G27: 5 | H27: 15 | I27: 0.1 | J27: 2 | K27: 503.2 | L27: 26.4 | M27: 476.8 | N27: 0 | O27: 0 | P27: 1 | Q27: =IF(COUNT('GA Runs'!M111:M115)=0,"",MIN('GA Runs'!M111:M115)) -> 503.19 | R27: =IF($Q27="","",INDEX('GA Runs'!E111:E115,MATCH($Q27,'GA Runs'!M111:M115,0))) -> 26.36 | S27: =IF($Q27="","",INDEX('GA Runs'!F111:F115,MATCH($Q27,'GA Runs'!M111:M115,0))) -> 476.83 | T27: =IF($Q27="","",INDEX('GA Runs'!G111:G115,MATCH($Q27,'GA Runs'!M111:M115,0))) -> 0 | U27: =IF($Q27="","",INDEX('GA Runs'!H111:H115,MATCH($Q27,'GA Runs'!M111:M115,0))) -> 0 | V27: =IF($Q27="","",INDEX('GA Runs'!I111:I115,MATCH($Q27,'GA Runs'!M111:M115,0))) -> 20.95 | W27: =IF(OR($K27="",$Q27="",NOT(ISNUMBER($K27))),"",100*($Q27-$K27)/$K27) -> -0.0019872814 | X27: =IF(COUNT('GA Runs'!M111:M115)=0,"",AVERAGE('GA Runs'!M111:M115)) -> 525.526 | Y27: =IF(COUNT('GA Runs'!M111:M115)<2,"",_xlfn.STDEV.S('GA Runs'!M111:M115)) -> 12.652371 | Z27: =COUNT('GA Runs'!M111:M115) -> 5 | AA27: =IF($Z27=0,"",AVERAGEIF('GA Runs'!M111:M115,">=0",'GA Runs'!I111:I115)) -> 21.164 | AB27: 958.14 | AC27: 508.93 | AD27: 449.21 | AE27: 0 | AF27: 0 | AG27: 1.03 | AH27: =IF(OR($AC27="",$R27="",$AC27=0),"",100*($AC27-$R27)/$AC27) -> 94.820506 | AI27: =IF($U27="","",100*($C27-$U27)/$C27) -> 100 | AJ27: =IF($AF27="","",100*($C27-$AF27)/$C27) -> 100 | AK27: =IF(OR($AI27="",$AJ27=""),"",$AI27-$AJ27) -> 0 | AL27: =IF($Q27="","",IF(ABS($Q27-SUM($R27:$T27))<0.05,"OK","CHECK")) -> OK
A28: 20-5-3 | B28: 73 | C28: 20 | D28: 4 | E28: 2 | F28: 0.5 | G28: 10 | H28: 10 | I28: 0.1 | J28: 2 | K28: 807.3 | L28: 278.4 | M28: 528.9 | N28: 0 | O28: 0 | P28: 5 | Q28: =IF(COUNT('GA Runs'!M116:M120)=0,"",MIN('GA Runs'!M116:M120)) -> 807.3 | R28: =IF($Q28="","",INDEX('GA Runs'!E116:E120,MATCH($Q28,'GA Runs'!M116:M120,0))) -> 278.42 | S28: =IF($Q28="","",INDEX('GA Runs'!F116:F120,MATCH($Q28,'GA Runs'!M116:M120,0))) -> 528.88 | T28: =IF($Q28="","",INDEX('GA Runs'!G116:G120,MATCH($Q28,'GA Runs'!M116:M120,0))) -> 0 | U28: =IF($Q28="","",INDEX('GA Runs'!H116:H120,MATCH($Q28,'GA Runs'!M116:M120,0))) -> 0 | V28: =IF($Q28="","",INDEX('GA Runs'!I116:I120,MATCH($Q28,'GA Runs'!M116:M120,0))) -> 16.01 | W28: =IF(OR($K28="",$Q28="",NOT(ISNUMBER($K28))),"",100*($Q28-$K28)/$K28) -> 0 | X28: =IF(COUNT('GA Runs'!M116:M120)=0,"",AVERAGE('GA Runs'!M116:M120)) -> 841.362 | Y28: =IF(COUNT('GA Runs'!M116:M120)<2,"",_xlfn.STDEV.S('GA Runs'!M116:M120)) -> 37.930893 | Z28: =COUNT('GA Runs'!M116:M120) -> 5 | AA28: =IF($Z28=0,"",AVERAGEIF('GA Runs'!M116:M120,">=0",'GA Runs'!I116:I120)) -> 15.89 | AB28: 1527.86 | AC28: 975.84 | AD28: 552.02 | AE28: 0 | AF28: 0 | AG28: 0.5 | AH28: =IF(OR($AC28="",$R28="",$AC28=0),"",100*($AC28-$R28)/$AC28) -> 71.468683 | AI28: =IF($U28="","",100*($C28-$U28)/$C28) -> 100 | AJ28: =IF($AF28="","",100*($C28-$AF28)/$C28) -> 100 | AK28: =IF(OR($AI28="",$AJ28=""),"",$AI28-$AJ28) -> 0 | AL28: =IF($Q28="","",IF(ABS($Q28-SUM($R28:$T28))<0.05,"OK","CHECK")) -> OK
A29: 20-5-4 | B29: 73 | C29: 20 | D29: 4 | E29: 2 | F29: 0.75 | G29: 15 | H29: 5 | I29: 0.1 | J29: 2 | K29: 936.4 | L29: 406 | M29: 530.4 | N29: 0 | O29: 0 | P29: 4 | Q29: =IF(COUNT('GA Runs'!M121:M125)=0,"",MIN('GA Runs'!M121:M125)) -> 936.39 | R29: =IF($Q29="","",INDEX('GA Runs'!E121:E125,MATCH($Q29,'GA Runs'!M121:M125,0))) -> 406 | S29: =IF($Q29="","",INDEX('GA Runs'!F121:F125,MATCH($Q29,'GA Runs'!M121:M125,0))) -> 530.39 | T29: =IF($Q29="","",INDEX('GA Runs'!G121:G125,MATCH($Q29,'GA Runs'!M121:M125,0))) -> 0 | U29: =IF($Q29="","",INDEX('GA Runs'!H121:H125,MATCH($Q29,'GA Runs'!M121:M125,0))) -> 0 | V29: =IF($Q29="","",INDEX('GA Runs'!I121:I125,MATCH($Q29,'GA Runs'!M121:M125,0))) -> 15.92 | W29: =IF(OR($K29="",$Q29="",NOT(ISNUMBER($K29))),"",100*($Q29-$K29)/$K29) -> -0.0010679197 | X29: =IF(COUNT('GA Runs'!M121:M125)=0,"",AVERAGE('GA Runs'!M121:M125)) -> 990.106 | Y29: =IF(COUNT('GA Runs'!M121:M125)<2,"",_xlfn.STDEV.S('GA Runs'!M121:M125)) -> 38.383234 | Z29: =COUNT('GA Runs'!M121:M125) -> 5 | AA29: =IF($Z29=0,"",AVERAGEIF('GA Runs'!M121:M125,">=0",'GA Runs'!I121:I125)) -> 15.912 | AB29: 1799.34 | AC29: 1240.48 | AD29: 558.87 | AE29: 0 | AF29: 0 | AG29: 0.79 | AH29: =IF(OR($AC29="",$R29="",$AC29=0),"",100*($AC29-$R29)/$AC29) -> 67.270734 | AI29: =IF($U29="","",100*($C29-$U29)/$C29) -> 100 | AJ29: =IF($AF29="","",100*($C29-$AF29)/$C29) -> 100 | AK29: =IF(OR($AI29="",$AJ29=""),"",$AI29-$AJ29) -> 0 | AL29: =IF($Q29="","",IF(ABS($Q29-SUM($R29:$T29))<0.05,"OK","CHECK")) -> OK
A30: 20-5-5 | B30: 73 | C30: 20 | D30: 4 | E30: 2 | F30: 0.9 | G30: 18 | H30: 2 | I30: 0.1 | J30: 2 | K30: 1354.8 | L30: 891.4 | M30: 463.4 | N30: 0 | O30: 0 | P30: 2225 | Q30: =IF(COUNT('GA Runs'!M126:M130)=0,"",MIN('GA Runs'!M126:M130)) -> 1357.49 | R30: =IF($Q30="","",INDEX('GA Runs'!E126:E130,MATCH($Q30,'GA Runs'!M126:M130,0))) -> 894.13 | S30: =IF($Q30="","",INDEX('GA Runs'!F126:F130,MATCH($Q30,'GA Runs'!M126:M130,0))) -> 463.37 | T30: =IF($Q30="","",INDEX('GA Runs'!G126:G130,MATCH($Q30,'GA Runs'!M126:M130,0))) -> 0 | U30: =IF($Q30="","",INDEX('GA Runs'!H126:H130,MATCH($Q30,'GA Runs'!M126:M130,0))) -> 0 | V30: =IF($Q30="","",INDEX('GA Runs'!I126:I130,MATCH($Q30,'GA Runs'!M126:M130,0))) -> 15.02 | W30: =IF(OR($K30="",$Q30="",NOT(ISNUMBER($K30))),"",100*($Q30-$K30)/$K30) -> 0.19855329 | X30: =IF(COUNT('GA Runs'!M126:M130)=0,"",AVERAGE('GA Runs'!M126:M130)) -> 1381.198 | Y30: =IF(COUNT('GA Runs'!M126:M130)<2,"",_xlfn.STDEV.S('GA Runs'!M126:M130)) -> 22.017245 | Z30: =COUNT('GA Runs'!M126:M130) -> 5 | AA30: =IF($Z30=0,"",AVERAGEIF('GA Runs'!M126:M130,">=0",'GA Runs'!I126:I130)) -> 15.13 | AB30: 2350.57 | AC30: 1870.89 | AD30: 479.68 | AE30: 0 | AF30: 0 | AG30: 0.89 | AH30: =IF(OR($AC30="",$R30="",$AC30=0),"",100*($AC30-$R30)/$AC30) -> 52.208307 | AI30: =IF($U30="","",100*($C30-$U30)/$C30) -> 100 | AJ30: =IF($AF30="","",100*($C30-$AF30)/$C30) -> 100 | AK30: =IF(OR($AI30="",$AJ30=""),"",$AI30-$AJ30) -> 0 | AL30: =IF($Q30="","",IF(ABS($Q30-SUM($R30:$T30))<0.05,"OK","CHECK")) -> OK
A31: 40-1-1 | B31: 5 | C31: 40 | D31: 8 | E31: 4 | F31: 0.1 | G31: 4 | H31: 36 | I31: 0.1 | J31: 4 | K31: 14868.3 | L31: 0 | M31: 868.3 | N31: 14000 | O31: 4 (4A) | P31: 175 | Q31: =IF(COUNT('GA Runs'!M131:M135)=0,"",MIN('GA Runs'!M131:M135)) -> 15857.752 | R31: =IF($Q31="","",INDEX('GA Runs'!E131:E135,MATCH($Q31,'GA Runs'!M131:M135,0))) -> 0 | S31: =IF($Q31="","",INDEX('GA Runs'!F131:F135,MATCH($Q31,'GA Runs'!M131:M135,0))) -> 857.752 | T31: =IF($Q31="","",INDEX('GA Runs'!G131:G135,MATCH($Q31,'GA Runs'!M131:M135,0))) -> 15000 | U31: =IF($Q31="","",INDEX('GA Runs'!H131:H135,MATCH($Q31,'GA Runs'!M131:M135,0))) -> 15 | V31: =IF($Q31="","",INDEX('GA Runs'!I131:I135,MATCH($Q31,'GA Runs'!M131:M135,0))) -> 38.416 | W31: =IF(OR($K31="",$Q31="",NOT(ISNUMBER($K31))),"",100*($Q31-$K31)/$K31) -> 6.6547756 | X31: =IF(COUNT('GA Runs'!M131:M135)=0,"",AVERAGE('GA Runs'!M131:M135)) -> 17311.055 | Y31: =IF(COUNT('GA Runs'!M131:M135)<2,"",_xlfn.STDEV.S('GA Runs'!M131:M135)) -> 1127.8179 | Z31: =COUNT('GA Runs'!M131:M135) -> 5 | AA31: =IF($Z31=0,"",AVERAGEIF('GA Runs'!M131:M135,">=0",'GA Runs'!I131:I135)) -> 39.0598 | AB31: 15271.76 | AC31: 343.28 | AD31: 928.49 | AE31: 14000 | AF31: 4 | AG31: 281.31 | AH31: =IF(OR($AC31="",$R31="",$AC31=0),"",100*($AC31-$R31)/$AC31) -> 100 | AI31: =IF($U31="","",100*($C31-$U31)/$C31) -> 62.5 | AJ31: =IF($AF31="","",100*($C31-$AF31)/$C31) -> 90 | AK31: =IF(OR($AI31="",$AJ31=""),"",$AI31-$AJ31) -> -27.5 | AL31: =IF($Q31="","",IF(ABS($Q31-SUM($R31:$T31))<0.05,"OK","CHECK")) -> OK
A32: 40-1-2 | B32: 5 | C32: 40 | D32: 8 | E32: 4 | F32: 0.25 | G32: 10 | H32: 30 | I32: 0.1 | J32: 4 | K32: 14978.6 | L32: 73.9 | M32: 904.7 | N32: 14000 | O32: 4 (4A) | P32: 47 | Q32: =IF(COUNT('GA Runs'!M136:M140)=0,"",MIN('GA Runs'!M136:M140)) -> 15004.813 | R32: =IF($Q32="","",INDEX('GA Runs'!E136:E140,MATCH($Q32,'GA Runs'!M136:M140,0))) -> 52.82 | S32: =IF($Q32="","",INDEX('GA Runs'!F136:F140,MATCH($Q32,'GA Runs'!M136:M140,0))) -> 951.993 | T32: =IF($Q32="","",INDEX('GA Runs'!G136:G140,MATCH($Q32,'GA Runs'!M136:M140,0))) -> 14000 | U32: =IF($Q32="","",INDEX('GA Runs'!H136:H140,MATCH($Q32,'GA Runs'!M136:M140,0))) -> 14 | V32: =IF($Q32="","",INDEX('GA Runs'!I136:I140,MATCH($Q32,'GA Runs'!M136:M140,0))) -> 40.321 | W32: =IF(OR($K32="",$Q32="",NOT(ISNUMBER($K32))),"",100*($Q32-$K32)/$K32) -> 0.175003 | X32: =IF(COUNT('GA Runs'!M136:M140)=0,"",AVERAGE('GA Runs'!M136:M140)) -> 16578.254 | Y32: =IF(COUNT('GA Runs'!M136:M140)<2,"",_xlfn.STDEV.S('GA Runs'!M136:M140)) -> 1131.3443 | Z32: =COUNT('GA Runs'!M136:M140) -> 5 | AA32: =IF($Z32=0,"",AVERAGEIF('GA Runs'!M136:M140,">=0",'GA Runs'!I136:I140)) -> 41.342 | AB32: 17769.29 | AC32: 847.13 | AD32: 922.16 | AE32: 16000 | AF32: 5 | AG32: 150.62 | AH32: =IF(OR($AC32="",$R32="",$AC32=0),"",100*($AC32-$R32)/$AC32) -> 93.764829 | AI32: =IF($U32="","",100*($C32-$U32)/$C32) -> 65 | AJ32: =IF($AF32="","",100*($C32-$AF32)/$C32) -> 87.5 | AK32: =IF(OR($AI32="",$AJ32=""),"",$AI32-$AJ32) -> -22.5 | AL32: =IF($Q32="","",IF(ABS($Q32-SUM($R32:$T32))<0.05,"OK","CHECK")) -> OK
A33: 40-1-3 | B33: 5 | C33: 40 | D33: 8 | E33: 4 | F33: 0.5 | G33: 20 | H33: 20 | I33: 0.1 | J33: 4 | K33: 15462.9 | L33: 554.7 | M33: 908.2 | N33: 14000 | O33: 4 (2A + 2D) | P33: 163 | Q33: =IF(COUNT('GA Runs'!M141:M145)=0,"",MIN('GA Runs'!M141:M145)) -> 15842.53 | R33: =IF($Q33="","",INDEX('GA Runs'!E141:E145,MATCH($Q33,'GA Runs'!M141:M145,0))) -> 909.81 | S33: =IF($Q33="","",INDEX('GA Runs'!F141:F145,MATCH($Q33,'GA Runs'!M141:M145,0))) -> 932.719 | T33: =IF($Q33="","",INDEX('GA Runs'!G141:G145,MATCH($Q33,'GA Runs'!M141:M145,0))) -> 14000 | U33: =IF($Q33="","",INDEX('GA Runs'!H141:H145,MATCH($Q33,'GA Runs'!M141:M145,0))) -> 14 | V33: =IF($Q33="","",INDEX('GA Runs'!I141:I145,MATCH($Q33,'GA Runs'!M141:M145,0))) -> 40.446 | W33: =IF(OR($K33="",$Q33="",NOT(ISNUMBER($K33))),"",100*($Q33-$K33)/$K33) -> 2.4551022 | X33: =IF(COUNT('GA Runs'!M141:M145)=0,"",AVERAGE('GA Runs'!M141:M145)) -> 17742.885 | Y33: =IF(COUNT('GA Runs'!M141:M145)<2,"",_xlfn.STDEV.S('GA Runs'!M141:M145)) -> 1285.8515 | Z33: =COUNT('GA Runs'!M141:M145) -> 5 | AA33: =IF($Z33=0,"",AVERAGEIF('GA Runs'!M141:M145,">=0",'GA Runs'!I141:I145)) -> 38.985 | AB33: 20394.86 | AC33: 1394.05 | AD33: 1000.8 | AE33: 18000 | AF33: 5 | AG33: 52.32 | AH33: =IF(OR($AC33="",$R33="",$AC33=0),"",100*($AC33-$R33)/$AC33) -> 34.7362 | AI33: =IF($U33="","",100*($C33-$U33)/$C33) -> 65 | AJ33: =IF($AF33="","",100*($C33-$AF33)/$C33) -> 87.5 | AK33: =IF(OR($AI33="",$AJ33=""),"",$AI33-$AJ33) -> -22.5 | AL33: =IF($Q33="","",IF(ABS($Q33-SUM($R33:$T33))<0.05,"OK","CHECK")) -> OK
A34: 40-1-4 | B34: 5 | C34: 40 | D34: 8 | E34: 4 | F34: 0.75 | G34: 30 | H34: 10 | I34: 0.1 | J34: 4 | K34: 15984.8 | L34: 1094 | M34: 890.8 | N34: 14000 | O34: 4 (2A + 2D) | P34: 544 | Q34: =IF(COUNT('GA Runs'!M146:M150)=0,"",MIN('GA Runs'!M146:M150)) -> 16187.873 | R34: =IF($Q34="","",INDEX('GA Runs'!E146:E150,MATCH($Q34,'GA Runs'!M146:M150,0))) -> 1243.09 | S34: =IF($Q34="","",INDEX('GA Runs'!F146:F150,MATCH($Q34,'GA Runs'!M146:M150,0))) -> 944.783 | T34: =IF($Q34="","",INDEX('GA Runs'!G146:G150,MATCH($Q34,'GA Runs'!M146:M150,0))) -> 14000 | U34: =IF($Q34="","",INDEX('GA Runs'!H146:H150,MATCH($Q34,'GA Runs'!M146:M150,0))) -> 14 | V34: =IF($Q34="","",INDEX('GA Runs'!I146:I150,MATCH($Q34,'GA Runs'!M146:M150,0))) -> 42.499 | W34: =IF(OR($K34="",$Q34="",NOT(ISNUMBER($K34))),"",100*($Q34-$K34)/$K34) -> 1.2704131 | X34: =IF(COUNT('GA Runs'!M146:M150)=0,"",AVERAGE('GA Runs'!M146:M150)) -> 17560.997 | Y34: =IF(COUNT('GA Runs'!M146:M150)<2,"",_xlfn.STDEV.S('GA Runs'!M146:M150)) -> 1252.298 | Z34: =COUNT('GA Runs'!M146:M150) -> 5 | AA34: =IF($Z34=0,"",AVERAGEIF('GA Runs'!M146:M150,">=0",'GA Runs'!I146:I150)) -> 39.7154 | AB34: 25885.03 | AC34: 1949.47 | AD34: 935.56 | AE34: 23000 | AF34: 6 | AG34: 2.3 | AH34: =IF(OR($AC34="",$R34="",$AC34=0),"",100*($AC34-$R34)/$AC34) -> 36.234464 | AI34: =IF($U34="","",100*($C34-$U34)/$C34) -> 65 | AJ34: =IF($AF34="","",100*($C34-$AF34)/$C34) -> 85 | AK34: =IF(OR($AI34="",$AJ34=""),"",$AI34-$AJ34) -> -20 | AL34: =IF($Q34="","",IF(ABS($Q34-SUM($R34:$T34))<0.05,"OK","CHECK")) -> OK
A35: 40-1-5 | B35: 5 | C35: 40 | D35: 8 | E35: 4 | F35: 0.9 | G35: 36 | H35: 4 | I35: 0.1 | J35: 4 | K35: N/A | L35: N/A | M35: N/A | N35: N/A | O35: N/A | P35: 21600 | Q35: =IF(COUNT('GA Runs'!M151:M155)=0,"",MIN('GA Runs'!M151:M155)) -> 15092.933 | R35: =IF($Q35="","",INDEX('GA Runs'!E151:E155,MATCH($Q35,'GA Runs'!M151:M155,0))) -> 1155.142 | S35: =IF($Q35="","",INDEX('GA Runs'!F151:F155,MATCH($Q35,'GA Runs'!M151:M155,0))) -> 937.791 | T35: =IF($Q35="","",INDEX('GA Runs'!G151:G155,MATCH($Q35,'GA Runs'!M151:M155,0))) -> 13000 | U35: =IF($Q35="","",INDEX('GA Runs'!H151:H155,MATCH($Q35,'GA Runs'!M151:M155,0))) -> 13 | V35: =IF($Q35="","",INDEX('GA Runs'!I151:I155,MATCH($Q35,'GA Runs'!M151:M155,0))) -> 40.99 | W35: =IF(OR($K35="",$Q35="",NOT(ISNUMBER($K35))),"",100*($Q35-$K35)/$K35) | X35: =IF(COUNT('GA Runs'!M151:M155)=0,"",AVERAGE('GA Runs'!M151:M155)) -> 15152.181 | Y35: =IF(COUNT('GA Runs'!M151:M155)<2,"",_xlfn.STDEV.S('GA Runs'!M151:M155)) -> 53.868773 | Z35: =COUNT('GA Runs'!M151:M155) -> 5 | AA35: =IF($Z35=0,"",AVERAGEIF('GA Runs'!M151:M155,">=0",'GA Runs'!I151:I155)) -> 39.2122 | AB35: 20618.97 | AC35: 2701.89 | AD35: 917.08 | AE35: 17000 | AF35: 5 | AG35: 4.74 | AH35: =IF(OR($AC35="",$R35="",$AC35=0),"",100*($AC35-$R35)/$AC35) -> 57.24689 | AI35: =IF($U35="","",100*($C35-$U35)/$C35) -> 67.5 | AJ35: =IF($AF35="","",100*($C35-$AF35)/$C35) -> 87.5 | AK35: =IF(OR($AI35="",$AJ35=""),"",$AI35-$AJ35) -> -20 | AL35: =IF($Q35="","",IF(ABS($Q35-SUM($R35:$T35))<0.05,"OK","CHECK")) -> OK
A36: 40-2-1 | B36: 73 | C36: 40 | D36: 8 | E36: 4 | F36: 0.1 | G36: 4 | H36: 36 | I36: 0.1 | J36: 4 | K36: 4163.1 | L36: 349.4 | M36: 813.7 | N36: 3000 | O36: 1 (1A) | P36: 23 | Q36: =IF(COUNT('GA Runs'!M156:M160)=0,"",MIN('GA Runs'!M156:M160)) -> 4170.231 | R36: =IF($Q36="","",INDEX('GA Runs'!E156:E160,MATCH($Q36,'GA Runs'!M156:M160,0))) -> 349.436 | S36: =IF($Q36="","",INDEX('GA Runs'!F156:F160,MATCH($Q36,'GA Runs'!M156:M160,0))) -> 820.795 | T36: =IF($Q36="","",INDEX('GA Runs'!G156:G160,MATCH($Q36,'GA Runs'!M156:M160,0))) -> 3000 | U36: =IF($Q36="","",INDEX('GA Runs'!H156:H160,MATCH($Q36,'GA Runs'!M156:M160,0))) -> 3 | V36: =IF($Q36="","",INDEX('GA Runs'!I156:I160,MATCH($Q36,'GA Runs'!M156:M160,0))) -> 43.443 | W36: =IF(OR($K36="",$Q36="",NOT(ISNUMBER($K36))),"",100*($Q36-$K36)/$K36) -> 0.17129062 | X36: =IF(COUNT('GA Runs'!M156:M160)=0,"",AVERAGE('GA Runs'!M156:M160)) -> 6981.1318 | Y36: =IF(COUNT('GA Runs'!M156:M160)<2,"",_xlfn.STDEV.S('GA Runs'!M156:M160)) -> 1608.7276 | Z36: =COUNT('GA Runs'!M156:M160) -> 5 | AA36: =IF($Z36=0,"",AVERAGEIF('GA Runs'!M156:M160,">=0",'GA Runs'!I156:I160)) -> 41.0614 | AB36: 4324.35 | AC36: 510.54 | AD36: 813.8 | AE36: 3000 | AF36: 1 | AG36: 11.16 | AH36: =IF(OR($AC36="",$R36="",$AC36=0),"",100*($AC36-$R36)/$AC36) -> 31.555608 | AI36: =IF($U36="","",100*($C36-$U36)/$C36) -> 92.5 | AJ36: =IF($AF36="","",100*($C36-$AF36)/$C36) -> 97.5 | AK36: =IF(OR($AI36="",$AJ36=""),"",$AI36-$AJ36) -> -5 | AL36: =IF($Q36="","",IF(ABS($Q36-SUM($R36:$T36))<0.05,"OK","CHECK")) -> OK
A37: 40-2-2 | B37: 73 | C37: 40 | D37: 8 | E37: 4 | F37: 0.25 | G37: 10 | H37: 30 | I37: 0.1 | J37: 4 | K37: 4398.8 | L37: 583.9 | M37: 815 | N37: 3000 | O37: 1 (1A) | P37: 34 | Q37: =IF(COUNT('GA Runs'!M161:M165)=0,"",MIN('GA Runs'!M161:M165)) -> 4488.228 | R37: =IF($Q37="","",INDEX('GA Runs'!E161:E165,MATCH($Q37,'GA Runs'!M161:M165,0))) -> 691.204 | S37: =IF($Q37="","",INDEX('GA Runs'!F161:F165,MATCH($Q37,'GA Runs'!M161:M165,0))) -> 797.024 | T37: =IF($Q37="","",INDEX('GA Runs'!G161:G165,MATCH($Q37,'GA Runs'!M161:M165,0))) -> 3000 | U37: =IF($Q37="","",INDEX('GA Runs'!H161:H165,MATCH($Q37,'GA Runs'!M161:M165,0))) -> 3 | V37: =IF($Q37="","",INDEX('GA Runs'!I161:I165,MATCH($Q37,'GA Runs'!M161:M165,0))) -> 44.216 | W37: =IF(OR($K37="",$Q37="",NOT(ISNUMBER($K37))),"",100*($Q37-$K37)/$K37) -> 2.033009 | X37: =IF(COUNT('GA Runs'!M161:M165)=0,"",AVERAGE('GA Runs'!M161:M165)) -> 4555.904 | Y37: =IF(COUNT('GA Runs'!M161:M165)<2,"",_xlfn.STDEV.S('GA Runs'!M161:M165)) -> 63.651172 | Z37: =COUNT('GA Runs'!M161:M165) -> 5 | AA37: =IF($Z37=0,"",AVERAGEIF('GA Runs'!M161:M165,">=0",'GA Runs'!I161:I165)) -> 43.1338 | AB37: 5020.24 | AC37: 1209.82 | AD37: 810.42 | AE37: 3000 | AF37: 1 | AG37: 13.98 | AH37: =IF(OR($AC37="",$R37="",$AC37=0),"",100*($AC37-$R37)/$AC37) -> 42.867203 | AI37: =IF($U37="","",100*($C37-$U37)/$C37) -> 92.5 | AJ37: =IF($AF37="","",100*($C37-$AF37)/$C37) -> 97.5 | AK37: =IF(OR($AI37="",$AJ37=""),"",$AI37-$AJ37) -> -5 | AL37: =IF($Q37="","",IF(ABS($Q37-SUM($R37:$T37))<0.05,"OK","CHECK")) -> OK
A38: 40-2-3 | B38: 73 | C38: 40 | D38: 8 | E38: 4 | F38: 0.5 | G38: 20 | H38: 20 | I38: 0.1 | J38: 4 | K38: 4357.2 | L38: 453.2 | M38: 904 | N38: 3000 | O38: 1 (1D) | P38: 21 | Q38: =IF(COUNT('GA Runs'!M166:M170)=0,"",MIN('GA Runs'!M166:M170)) -> 4364.67 | R38: =IF($Q38="","",INDEX('GA Runs'!E166:E170,MATCH($Q38,'GA Runs'!M166:M170,0))) -> 458.359 | S38: =IF($Q38="","",INDEX('GA Runs'!F166:F170,MATCH($Q38,'GA Runs'!M166:M170,0))) -> 906.31 | T38: =IF($Q38="","",INDEX('GA Runs'!G166:G170,MATCH($Q38,'GA Runs'!M166:M170,0))) -> 3000 | U38: =IF($Q38="","",INDEX('GA Runs'!H166:H170,MATCH($Q38,'GA Runs'!M166:M170,0))) -> 3 | V38: =IF($Q38="","",INDEX('GA Runs'!I166:I170,MATCH($Q38,'GA Runs'!M166:M170,0))) -> 46.977 | W38: =IF(OR($K38="",$Q38="",NOT(ISNUMBER($K38))),"",100*($Q38-$K38)/$K38) -> 0.17144037 | X38: =IF(COUNT('GA Runs'!M166:M170)=0,"",AVERAGE('GA Runs'!M166:M170)) -> 4408.3748 | Y38: =IF(COUNT('GA Runs'!M166:M170)<2,"",_xlfn.STDEV.S('GA Runs'!M166:M170)) -> 33.029958 | Z38: =COUNT('GA Runs'!M166:M170) -> 5 | AA38: =IF($Z38=0,"",AVERAGEIF('GA Runs'!M166:M170,">=0",'GA Runs'!I166:I170)) -> 43.4704 | AB38: 6470.7 | AC38: 1505.09 | AD38: 965.62 | AE38: 4000 | AF38: 1 | AG38: 3.17 | AH38: =IF(OR($AC38="",$R38="",$AC38=0),"",100*($AC38-$R38)/$AC38) -> 69.546074 | AI38: =IF($U38="","",100*($C38-$U38)/$C38) -> 92.5 | AJ38: =IF($AF38="","",100*($C38-$AF38)/$C38) -> 97.5 | AK38: =IF(OR($AI38="",$AJ38=""),"",$AI38-$AJ38) -> -5 | AL38: =IF($Q38="","",IF(ABS($Q38-SUM($R38:$T38))<0.05,"OK","CHECK")) -> OK
A39: 40-2-4 | B39: 73 | C39: 40 | D39: 8 | E39: 4 | F39: 0.75 | G39: 30 | H39: 10 | I39: 0.1 | J39: 4 | K39: 5028 | L39: 1083.5 | M39: 944.5 | N39: 3000 | O39: 1 (1D) | P39: 1295 | Q39: =IF(COUNT('GA Runs'!M171:M175)=0,"",MIN('GA Runs'!M171:M175)) -> 5054.642 | R39: =IF($Q39="","",INDEX('GA Runs'!E171:E175,MATCH($Q39,'GA Runs'!M171:M175,0))) -> 1118.519 | S39: =IF($Q39="","",INDEX('GA Runs'!F171:F175,MATCH($Q39,'GA Runs'!M171:M175,0))) -> 936.123 | T39: =IF($Q39="","",INDEX('GA Runs'!G171:G175,MATCH($Q39,'GA Runs'!M171:M175,0))) -> 3000 | U39: =IF($Q39="","",INDEX('GA Runs'!H171:H175,MATCH($Q39,'GA Runs'!M171:M175,0))) -> 3 | V39: =IF($Q39="","",INDEX('GA Runs'!I171:I175,MATCH($Q39,'GA Runs'!M171:M175,0))) -> 45.711 | W39: =IF(OR($K39="",$Q39="",NOT(ISNUMBER($K39))),"",100*($Q39-$K39)/$K39) -> 0.52987271 | X39: =IF(COUNT('GA Runs'!M171:M175)=0,"",AVERAGE('GA Runs'!M171:M175)) -> 5111.764 | Y39: =IF(COUNT('GA Runs'!M171:M175)<2,"",_xlfn.STDEV.S('GA Runs'!M171:M175)) -> 44.678037 | Z39: =COUNT('GA Runs'!M171:M175) -> 5 | AA39: =IF($Z39=0,"",AVERAGEIF('GA Runs'!M171:M175,">=0",'GA Runs'!I171:I175)) -> 45.8918 | AB39: 10277.64 | AC39: 2306.15 | AD39: 971.49 | AE39: 7000 | AF39: 2 | AG39: 3.22 | AH39: =IF(OR($AC39="",$R39="",$AC39=0),"",100*($AC39-$R39)/$AC39) -> 51.498428 | AI39: =IF($U39="","",100*($C39-$U39)/$C39) -> 92.5 | AJ39: =IF($AF39="","",100*($C39-$AF39)/$C39) -> 95 | AK39: =IF(OR($AI39="",$AJ39=""),"",$AI39-$AJ39) -> -2.5 | AL39: =IF($Q39="","",IF(ABS($Q39-SUM($R39:$T39))<0.05,"OK","CHECK")) -> OK
A40: 40-2-5 | B40: 73 | C40: 40 | D40: 8 | E40: 4 | F40: 0.9 | G40: 36 | H40: 4 | I40: 0.1 | J40: 4 | K40: 6467.2 | L40: 1501 | M40: 966.2 | N40: 4000 | O40: 1 (1D) | P40: 923 | Q40: =IF(COUNT('GA Runs'!M176:M180)=0,"",MIN('GA Runs'!M176:M180)) -> 6527.983 | R40: =IF($Q40="","",INDEX('GA Runs'!E176:E180,MATCH($Q40,'GA Runs'!M176:M180,0))) -> 1535.148 | S40: =IF($Q40="","",INDEX('GA Runs'!F176:F180,MATCH($Q40,'GA Runs'!M176:M180,0))) -> 992.835 | T40: =IF($Q40="","",INDEX('GA Runs'!G176:G180,MATCH($Q40,'GA Runs'!M176:M180,0))) -> 4000 | U40: =IF($Q40="","",INDEX('GA Runs'!H176:H180,MATCH($Q40,'GA Runs'!M176:M180,0))) -> 4 | V40: =IF($Q40="","",INDEX('GA Runs'!I176:I180,MATCH($Q40,'GA Runs'!M176:M180,0))) -> 44.388 | W40: =IF(OR($K40="",$Q40="",NOT(ISNUMBER($K40))),"",100*($Q40-$K40)/$K40) -> 0.93986578 | X40: =IF(COUNT('GA Runs'!M176:M180)=0,"",AVERAGE('GA Runs'!M176:M180)) -> 6906.568 | Y40: =IF(COUNT('GA Runs'!M176:M180)<2,"",_xlfn.STDEV.S('GA Runs'!M176:M180)) -> 821.04903 | Z40: =COUNT('GA Runs'!M176:M180) -> 5 | AA40: =IF($Z40=0,"",AVERAGEIF('GA Runs'!M176:M180,">=0",'GA Runs'!I176:I180)) -> 45.0972 | AB40: 10592.87 | AC40: 2622.29 | AD40: 970.58 | AE40: 7000 | AF40: 2 | AG40: 4.85 | AH40: =IF(OR($AC40="",$R40="",$AC40=0),"",100*($AC40-$R40)/$AC40) -> 41.457734 | AI40: =IF($U40="","",100*($C40-$U40)/$C40) -> 90 | AJ40: =IF($AF40="","",100*($C40-$AF40)/$C40) -> 95 | AK40: =IF(OR($AI40="",$AJ40=""),"",$AI40-$AJ40) -> -5 | AL40: =IF($Q40="","",IF(ABS($Q40-SUM($R40:$T40))<0.05,"OK","CHECK")) -> OK
A41: 40-3-1 | B41: 20 | C41: 40 | D41: 8 | E41: 4 | F41: 0.1 | G41: 4 | H41: 36 | I41: 0.1 | J41: 4 | K41: 9909.7 | L41: 20.8 | M41: 888.9 | N41: 9000 | O41: 3 (3A) | P41: 610 | Q41: =IF(COUNT('GA Runs'!M181:M185)=0,"",MIN('GA Runs'!M181:M185)) -> 9948.301 | R41: =IF($Q41="","",INDEX('GA Runs'!E181:E185,MATCH($Q41,'GA Runs'!M181:M185,0))) -> 20.801 | S41: =IF($Q41="","",INDEX('GA Runs'!F181:F185,MATCH($Q41,'GA Runs'!M181:M185,0))) -> 927.5 | T41: =IF($Q41="","",INDEX('GA Runs'!G181:G185,MATCH($Q41,'GA Runs'!M181:M185,0))) -> 9000 | U41: =IF($Q41="","",INDEX('GA Runs'!H181:H185,MATCH($Q41,'GA Runs'!M181:M185,0))) -> 9 | V41: =IF($Q41="","",INDEX('GA Runs'!I181:I185,MATCH($Q41,'GA Runs'!M181:M185,0))) -> 43.789 | W41: =IF(OR($K41="",$Q41="",NOT(ISNUMBER($K41))),"",100*($Q41-$K41)/$K41) -> 0.38952743 | X41: =IF(COUNT('GA Runs'!M181:M185)=0,"",AVERAGE('GA Runs'!M181:M185)) -> 12922.751 | Y41: =IF(COUNT('GA Runs'!M181:M185)<2,"",_xlfn.STDEV.S('GA Runs'!M181:M185)) -> 3862.164 | Z41: =COUNT('GA Runs'!M181:M185) -> 5 | AA41: =IF($Z41=0,"",AVERAGEIF('GA Runs'!M181:M185,">=0",'GA Runs'!I181:I185)) -> 41.3956 | AB41: 10328.11 | AC41: 435.38 | AD41: 892.73 | AE41: 9000 | AF41: 3 | AG41: 53.53 | AH41: =IF(OR($AC41="",$R41="",$AC41=0),"",100*($AC41-$R41)/$AC41) -> 95.222335 | AI41: =IF($U41="","",100*($C41-$U41)/$C41) -> 77.5 | AJ41: =IF($AF41="","",100*($C41-$AF41)/$C41) -> 92.5 | AK41: =IF(OR($AI41="",$AJ41=""),"",$AI41-$AJ41) -> -15 | AL41: =IF($Q41="","",IF(ABS($Q41-SUM($R41:$T41))<0.05,"OK","CHECK")) -> OK
A42: 40-3-2 | B42: 20 | C42: 40 | D42: 8 | E42: 4 | F42: 0.25 | G42: 10 | H42: 30 | I42: 0.1 | J42: 4 | K42: 9984.2 | L42: 63.4 | M42: 920.8 | N42: 9000 | O42: 3 (2A + 1D) | P42: 198 | Q42: =IF(COUNT('GA Runs'!M186:M190)=0,"",MIN('GA Runs'!M186:M190)) -> 10235.616 | R42: =IF($Q42="","",INDEX('GA Runs'!E186:E190,MATCH($Q42,'GA Runs'!M186:M190,0))) -> 264.656 | S42: =IF($Q42="","",INDEX('GA Runs'!F186:F190,MATCH($Q42,'GA Runs'!M186:M190,0))) -> 970.96 | T42: =IF($Q42="","",INDEX('GA Runs'!G186:G190,MATCH($Q42,'GA Runs'!M186:M190,0))) -> 9000 | U42: =IF($Q42="","",INDEX('GA Runs'!H186:H190,MATCH($Q42,'GA Runs'!M186:M190,0))) -> 9 | V42: =IF($Q42="","",INDEX('GA Runs'!I186:I190,MATCH($Q42,'GA Runs'!M186:M190,0))) -> 42.638 | W42: =IF(OR($K42="",$Q42="",NOT(ISNUMBER($K42))),"",100*($Q42-$K42)/$K42) -> 2.5181387 | X42: =IF(COUNT('GA Runs'!M186:M190)=0,"",AVERAGE('GA Runs'!M186:M190)) -> 11070.507 | Y42: =IF(COUNT('GA Runs'!M186:M190)<2,"",_xlfn.STDEV.S('GA Runs'!M186:M190)) -> 1272.8514 | Z42: =COUNT('GA Runs'!M186:M190) -> 5 | AA42: =IF($Z42=0,"",AVERAGEIF('GA Runs'!M186:M190,">=0",'GA Runs'!I186:I190)) -> 43.2814 | AB42: 15618.51 | AC42: 643.02 | AD42: 975.48 | AE42: 14000 | AF42: 4 | AG42: 6.76 | AH42: =IF(OR($AC42="",$R42="",$AC42=0),"",100*($AC42-$R42)/$AC42) -> 58.841716 | AI42: =IF($U42="","",100*($C42-$U42)/$C42) -> 77.5 | AJ42: =IF($AF42="","",100*($C42-$AF42)/$C42) -> 90 | AK42: =IF(OR($AI42="",$AJ42=""),"",$AI42-$AJ42) -> -12.5 | AL42: =IF($Q42="","",IF(ABS($Q42-SUM($R42:$T42))<0.05,"OK","CHECK")) -> OK
A43: 40-3-3 | B43: 20 | C43: 40 | D43: 8 | E43: 4 | F43: 0.5 | G43: 20 | H43: 20 | I43: 0.1 | J43: 4 | K43: 8539.5 | L43: 601.9 | M43: 937.5 | N43: 7000 | O43: 2 (2A) | P43: 3551 | Q43: =IF(COUNT('GA Runs'!M191:M195)=0,"",MIN('GA Runs'!M191:M195)) -> 8618.753 | R43: =IF($Q43="","",INDEX('GA Runs'!E191:E195,MATCH($Q43,'GA Runs'!M191:M195,0))) -> 606.908 | S43: =IF($Q43="","",INDEX('GA Runs'!F191:F195,MATCH($Q43,'GA Runs'!M191:M195,0))) -> 1011.845 | T43: =IF($Q43="","",INDEX('GA Runs'!G191:G195,MATCH($Q43,'GA Runs'!M191:M195,0))) -> 7000 | U43: =IF($Q43="","",INDEX('GA Runs'!H191:H195,MATCH($Q43,'GA Runs'!M191:M195,0))) -> 7 | V43: =IF($Q43="","",INDEX('GA Runs'!I191:I195,MATCH($Q43,'GA Runs'!M191:M195,0))) -> 43.479 | W43: =IF(OR($K43="",$Q43="",NOT(ISNUMBER($K43))),"",100*($Q43-$K43)/$K43) -> 0.92807541 | X43: =IF(COUNT('GA Runs'!M191:M195)=0,"",AVERAGE('GA Runs'!M191:M195)) -> 9854.6508 | Y43: =IF(COUNT('GA Runs'!M191:M195)<2,"",_xlfn.STDEV.S('GA Runs'!M191:M195)) -> 1560.7803 | Z43: =COUNT('GA Runs'!M191:M195) -> 5 | AA43: =IF($Z43=0,"",AVERAGEIF('GA Runs'!M191:M195,">=0",'GA Runs'!I191:I195)) -> 39.1462 | AB43: 14358.23 | AC43: 1408.37 | AD43: 949.87 | AE43: 12000 | AF43: 3 | AG43: 5.49 | AH43: =IF(OR($AC43="",$R43="",$AC43=0),"",100*($AC43-$R43)/$AC43) -> 56.907063 | AI43: =IF($U43="","",100*($C43-$U43)/$C43) -> 82.5 | AJ43: =IF($AF43="","",100*($C43-$AF43)/$C43) -> 92.5 | AK43: =IF(OR($AI43="",$AJ43=""),"",$AI43-$AJ43) -> -10 | AL43: =IF($Q43="","",IF(ABS($Q43-SUM($R43:$T43))<0.05,"OK","CHECK")) -> OK
...

Sheet GA Runs
A2: GA Replications
A3: Enter one row per run. A run is used in the Results summary only when Feasible and Validator Passed are both Yes.
A5: Instance | B5: Run | C5: GA Seed | D5: ZT | E5: Zd | F5: Zt2 | G5: Zu | H5: Uncovered | I5: Runtime (s) | J5: Feasible | K5: Validator Passed | L5: Notes | M5: Eligible ZT
A6: 20-1-1 | B6: 1 | C6: 0 | D6: 448.81 | E6: 0 | F6: 448.81 | G6: 0 | H6: 0 | I6: 20.5 | J6: Yes | K6: Yes | M6: =IF(AND(J6="Yes",K6="Yes",ISNUMBER(D6)),D6,"") -> 448.81
A7: 20-1-1 | B7: 2 | C7: 1 | D7: 448.81 | E7: 0 | F7: 448.81 | G7: 0 | H7: 0 | I7: 21.08 | J7: Yes | K7: Yes | M7: =IF(AND(J7="Yes",K7="Yes",ISNUMBER(D7)),D7,"") -> 448.81
A8: 20-1-1 | B8: 3 | C8: 2 | D8: 448.81 | E8: 0 | F8: 448.81 | G8: 0 | H8: 0 | I8: 21.87 | J8: Yes | K8: Yes | M8: =IF(AND(J8="Yes",K8="Yes",ISNUMBER(D8)),D8,"") -> 448.81
A9: 20-1-1 | B9: 4 | C9: 3 | D9: 448.81 | E9: 0 | F9: 448.81 | G9: 0 | H9: 0 | I9: 22.5 | J9: Yes | K9: Yes | M9: =IF(AND(J9="Yes",K9="Yes",ISNUMBER(D9)),D9,"") -> 448.81
A10: 20-1-1 | B10: 5 | C10: 4 | D10: 448.81 | E10: 0 | F10: 448.81 | G10: 0 | H10: 0 | I10: 22.98 | J10: Yes | K10: Yes | M10: =IF(AND(J10="Yes",K10="Yes",ISNUMBER(D10)),D10,"") -> 448.81
A11: 20-1-2 | B11: 1 | C11: 0 | D11: 569.87 | E11: 49.36 | F11: 520.5 | G11: 0 | H11: 0 | I11: 22.3 | J11: Yes | K11: Yes | M11: =IF(AND(J11="Yes",K11="Yes",ISNUMBER(D11)),D11,"") -> 569.87
A12: 20-1-2 | B12: 2 | C12: 1 | D12: 549.85 | E12: 38.2 | F12: 511.65 | G12: 0 | H12: 0 | I12: 23.24 | J12: Yes | K12: Yes | M12: =IF(AND(J12="Yes",K12="Yes",ISNUMBER(D12)),D12,"") -> 549.85
A13: 20-1-2 | B13: 3 | C13: 2 | D13: 549.85 | E13: 38.2 | F13: 511.65 | G13: 0 | H13: 0 | I13: 23.31 | J13: Yes | K13: Yes | M13: =IF(AND(J13="Yes",K13="Yes",ISNUMBER(D13)),D13,"") -> 549.85
A14: 20-1-2 | B14: 4 | C14: 3 | D14: 550.03 | E14: 32.98 | F14: 517.05 | G14: 0 | H14: 0 | I14: 23.78 | J14: Yes | K14: Yes | M14: =IF(AND(J14="Yes",K14="Yes",ISNUMBER(D14)),D14,"") -> 550.03
A15: 20-1-2 | B15: 5 | C15: 4 | D15: 549.85 | E15: 38.2 | F15: 511.65 | G15: 0 | H15: 0 | I15: 23.73 | J15: Yes | K15: Yes | M15: =IF(AND(J15="Yes",K15="Yes",ISNUMBER(D15)),D15,"") -> 549.85
A16: 20-1-3 | B16: 1 | C16: 0 | D16: 617.26 | E16: 60.07 | F16: 557.19 | G16: 0 | H16: 0 | I16: 23.27 | J16: Yes | K16: Yes | M16: =IF(AND(J16="Yes",K16="Yes",ISNUMBER(D16)),D16,"") -> 617.26
A17: 20-1-3 | B17: 2 | C17: 1 | D17: 586.33 | E17: 55.55 | F17: 530.78 | G17: 0 | H17: 0 | I17: 23.97 | J17: Yes | K17: Yes | M17: =IF(AND(J17="Yes",K17="Yes",ISNUMBER(D17)),D17,"") -> 586.33
... A505: 80-5-5 | B505: 5 | C505: 4 | D505: 21589.845 | E505: 5793.586 | F505: 1796.259 | G505: 14000 | H505: 14 | I505: 89.103 | J505: Yes | K505: Yes | M505: =IF(AND(J505="Yes",K505="Yes",ISNUMBER(D505)),D505,"") -> 21589.845
